Workbook

Sheet Instructions & Legend
A1: Adobe Target Web SDK End-to-End Test Checklist
A2: Operational QA tracker based on the latest available Target inventory. Preserve IDs as text, replace To Be Confirmed values with approved facts, and link every failure to a defect and evidence.
A4: Purpose | B4: Use this workbook to plan, execute, evidence, reconcile, and approve Adobe Target continuity testing during migration to Adobe Experience Platform Web SDK.
A5: How to use | B5: 1. Confirm open items and environment values. 2. Review risk-based activity selection. 3. Complete parameter and audience test data. 4. Execute Test Case Master rows. 5. Update supporting validation sheets. 6. Link evidence and defects. 7. Complete production smoke. 8. Obtain sign-off.
A6: Traceability | B6: Every test case is linked to a generic migration risk or an approved activity. Every Fail should have a Defect ID and evidence. A proposition response alone is not proof of visible rendering.
A7: Data quality | B7: Source inventory: 106 activities, 431 detail mappings, 117 offers, 292 audiences. Reconciliation parity passes. Profile script rows: 0.
A8: Status | B8: Definition | C8: Use
A9: Not Started | B9: Execution has not begun. | C9: Initial status for planned rows.
A10: In Progress | B10: Execution or evidence collection is underway. | C10: Use until all expected results and evidence are complete.
A11: Pass | B11: Expected result is met with sufficient evidence. | C11: Use only after request, response, rendering, and reporting checks applicable to the row pass.
A12: Fail | B12: Expected result is not met. | C12: Create or link a defect and evidence.
A13: Blocked | B13: Execution cannot proceed because access, data, environment, or dependency is unavailable. | C13: Record blocker, owner, and next action.
A14: N/A | B14: The control is demonstrably not applicable. | C14: Record the reason; do not use N/A to avoid unavailable data.
A15: Severity | B15: Definition | C15: Example
A16: Critical | B16: Release-stopping privacy, broad site failure, severe data loss, or critical personalization/reporting failure. | C16: Unauthorized data, site outage, or widespread duplicate conversion reporting.
A17: High | B17: Major qualification, rendering, or reporting failure with significant business impact. | C17: Approved critical activity does not qualify, render, or report.
A18: Medium | B18: Limited issue with a workaround or constrained impact. | C18: Browser-specific visual or interaction issue.
A19: Low | B19: Minor visual, documentation, or low-impact inconsistency. | C19: Small spacing issue with no functional/reporting impact.
... A23: Security | B23: Mask customer identifiers, access tokens, cookies, emails, and sensitive profile values. Do not paste secrets into workbook cells or evidence links. | C23: Use stable approved evidence storage.

Sheet Test Summary Dashboard
A1: Adobe Target Web SDK Test Summary Dashboard
A2: Formula-driven execution view. Activities Covered/Not Covered use the selected approved production-smoke population; business-group values remain To Be Confirmed until confirmed by owners.
A4: Test Execution | B4: Count | D4: Readiness & Coverage | E4: Value
A5: Total Test Cases | B5: =COUNTA('Test Case Master'!$A$5:$A$5000) -> 73 | D5: Inventory Activities | E5: 106
A6: Not Started | B6: =COUNTIF('Test Case Master'!$U$5:$U$5000,"Not Started") -> 73 | D6: Selected Active Activities | E6: =COUNTA('Production Smoke & Monitoring'!$A$5:$A$1000) -> 43
A7: In Progress | B7: =COUNTIF('Test Case Master'!$U$5:$U$5000,"In Progress") -> 0 | D7: Activities Covered | E7: =COUNTIF('Production Smoke & Monitoring'!$Q$5:$Q$1000,"Pass") -> 0
A8: Pass | B8: =COUNTIF('Test Case Master'!$U$5:$U$5000,"Pass") -> 0 | D8: Activities Not Covered | E8: =E6-E7 -> 43
A9: Fail | B9: =COUNTIF('Test Case Master'!$U$5:$U$5000,"Fail") -> 0 | D9: Open Defects | E9: =COUNTIFS('Evidence & Defect Log'!$A$5:$A$1000,"<>",'Evidence & Defect Log'!$N$5:$N$1000,"<>Closed") -> 0
A10: Blocked | B10: =COUNTIF('Test Case Master'!$U$5:$U$5000,"Blocked") -> 0 | D10: Open Critical Defects | E10: =COUNTIFS('Evidence & Defect Log'!$A$5:$A$1000,"<>",'Evidence & Defect Log'!$H$5:$H$1000,"Critical",'Evidence & Defect Log'!$N$5:$N$1000,"<>Closed") -> 0
A11: N/A | B11: =COUNTIF('Test Case Master'!$U$5:$U$5000,"N/A") -> 0 | D11: Open High Defects | E11: =COUNTIFS('Evidence & Defect Log'!$A$5:$A$1000,"<>",'Evidence & Defect Log'!$H$5:$H$1000,"High",'Evidence & Defect Log'!$N$5:$N$1000,"<>Closed") -> 0
A12: Pass Percentage | B12: =IFERROR(B8/(B8+B9+B10),0) -> 0 | D12: Open Medium Defects | E12: =COUNTIFS('Evidence & Defect Log'!$A$5:$A$1000,"<>",'Evidence & Defect Log'!$H$5:$H$1000,"Medium",'Evidence & Defect Log'!$N$5:$N$1000,"<>Closed") -> 0
D13: Open Low Defects | E13: =COUNTIFS('Evidence & Defect Log'!$A$5:$A$1000,"<>",'Evidence & Defect Log'!$H$5:$H$1000,"Low",'Evidence & Defect Log'!$N$5:$N$1000,"<>Closed") -> 0
D14: Readiness Status | E14: =IF(AND(E10=0,E11=0,COUNTIFS('Test Case Master'!$A$5:$A$5000,"<>",'Test Case Master'!$U$5:$U$5000,"<>Pass",'Test Case Master'!$U$5:$U$5000,"<>N/A")=0,COUNTA('Production Smoke & Monitoring'!$A$5:$A$1000)>0,COUNTIFS('Production Smoke & Monitoring'!$A$5:$A$1000,"<>",'Production Smoke & Monitoring'!$Q$5:$Q$1000,"<>Pass",'Production Smoke & Monitoring'!$Q$5:$Q$1000,"<>N/A")=0),"Ready","Not Ready") -> Not Ready
D15: Profile Script Rows | E15: 0
A17: Business Group Coverage | B17: Planned Activity Tests | C17: Passed | E17: Coverage Segment | F17: Inventory / Planned | G17: Passed
A18: CT | B18: =COUNTIFS('Test Case Master'!$D$5:$D$5000,A18,'Test Case Master'!$E$5:$E$5000,"<>To Be Confirmed") -> 0 | C18: =COUNTIFS('Test Case Master'!$D$5:$D$5000,A18,'Test Case Master'!$E$5:$E$5000,"<>To Be Confirmed",'Test Case Master'!$U$5:$U$5000,"Pass") -> 0 | E18: Analytics reporting | F18: =COUNTIFS('Test Case Master'!$H$5:$H$5000,"Analytics",'Test Case Master'!$E$5:$E$5000,"<>To Be Confirmed") -> 0 | G18: =COUNTIFS('Test Case Master'!$H$5:$H$5000,"Analytics",'Test Case Master'!$U$5:$U$5000,"Pass") -> 0
A19: OAO | B19: =COUNTIFS('Test Case Master'!$D$5:$D$5000,A19,'Test Case Master'!$E$5:$E$5000,"<>To Be Confirmed") -> 0 | C19: =COUNTIFS('Test Case Master'!$D$5:$D$5000,A19,'Test Case Master'!$E$5:$E$5000,"<>To Be Confirmed",'Test Case Master'!$U$5:$U$5000,"Pass") -> 0 | E19: Target reporting | F19: =COUNTIFS('Test Case Master'!$H$5:$H$5000,"target",'Test Case Master'!$E$5:$E$5000,"<>To Be Confirmed") -> 43 | G19: =COUNTIFS('Test Case Master'!$H$5:$H$5000,"target",'Test Case Master'!$U$5:$U$5000,"Pass") -> 0
A20: D1 | B20: =COUNTIFS('Test Case Master'!$D$5:$D$5000,A20,'Test Case Master'!$E$5:$E$5000,"<>To Be Confirmed") -> 0 | C20: =COUNTIFS('Test Case Master'!$D$5:$D$5000,A20,'Test Case Master'!$E$5:$E$5000,"<>To Be Confirmed",'Test Case Master'!$U$5:$U$5000,"Pass") -> 0 | E20: SPA activities | F20: =COUNTIF('Activity Coverage Matrix'!$O$5:$O$5000,"Yes") -> 0 | G20: =COUNTIFS('Activity Coverage Matrix'!$O$5:$O$5000,"Yes",'Activity Coverage Matrix'!$Y$5:$Y$5000,"Pass") -> 0
A21: To Be Confirmed | B21: =COUNTIFS('Test Case Master'!$D$5:$D$5000,A21,'Test Case Master'!$E$5:$E$5000,"<>To Be Confirmed") -> 43 | C21: =COUNTIFS('Test Case Master'!$D$5:$D$5000,A21,'Test Case Master'!$E$5:$E$5000,"<>To Be Confirmed",'Test Case Master'!$U$5:$U$5000,"Pass") -> 0 | E21: Custom-code mapping rows | F21: =COUNTIF('Activity Coverage Matrix'!$P$5:$P$5000,"Yes*") -> 381 | G21: =COUNTIFS('Activity Coverage Matrix'!$P$5:$P$5000,"Yes*",'Activity Coverage Matrix'!$Y$5:$Y$5000,"Pass") -> 0
E22: Browser matrix | F22: =COUNTA('Browser & Regression Matrix'!$A$5:$A$1000) -> 12 | G22: =COUNTIF('Browser & Regression Matrix'!$N$5:$N$1000,"Pass") -> 0

Sheet Activity Coverage Matrix
A1: Activity Coverage Matrix
A2: One row per activity, experience, and option-location mapping from the 22-column Activity Details Inventory. Audience levels remain separated in the displayed value.
A4: Coverage ID | B4: Business Group | C4: Activity ID | D4: Activity Name | E4: Activity Type | F4: Activity State | G4: Business Criticality | H4: Reporting Source | I4: Experience Name | J4: Audience IDs | K4: Location Type | L4: Location Name | M4: Offer ID | N4: Offer Name | O4: SPA Dependency | P4: Custom Code | Q4: Profile Parameter Dependency | R4: Mbox Parameter Dependency | S4: Analytics Event Dependency | T4: Target Metric Dependency | U4: Risk Rating | V4: Selected for Detailed Testing | W4: Selection Reason | X4: Test Case IDs | Y4: Coverage Status | Z4: Comments
A5: COV-0001 | B5: To Be Confirmed | C5: 270202 | D5: [GS-POC] 2024 Full Year and Fourth Quarter Earnings Results | E5: xt | F5: saved | G5: To Be Confirmed | H5: target | I5: Experience A | J5: Location: 3028922 | K5: selector | L5: Location 0 - h1 | M5: 0 | N5: Offer2 | O5: To Be Confirmed | P5: Yes - offer template evidence | Q5: No evidence in inventory | R5: No evidence in inventory | S5: N/A - Target reporting source | T5: Yes | U5: Medium | V5: No | W5: Saved/inactive; retain for traceability and select if reactivated or confirmed business-critical. | X5: - | Y5: Not Started | Z5: No shared-location evidence found for this activity.
A6: COV-0002 | B6: To Be Confirmed | C6: 263527 | D6: [POC-GS] Header notice | E6: xt | F6: saved | G6: To Be Confirmed | H6: target | I6: Experience A | J6: Location: 2943176 | K6: selector | L6: Location 0 - header | M6: 0 | N6: Offer2 | O6: To Be Confirmed | P6: Yes - offer template evidence | Q6: No evidence in inventory | R6: No evidence in inventory | S6: N/A - Target reporting source | T6: Yes | U6: Medium | V6: No | W6: Saved/inactive; retain for traceability and select if reactivated or confirmed business-critical. | X6: - | Y6: Not Started | Z6: No shared-location evidence found for this activity.
A7: COV-0003 | B7: To Be Confirmed | C7: 263527 | D7: [POC-GS] Header notice | E7: xt | F7: saved | G7: To Be Confirmed | H7: target | I7: Experience A | J7: Location: 2943176 | K7: selector | L7: Location 1 - HTML > BODY > DIV:nth-of-type(1) > DIV:nth-of-type(1) > DIV:nth-of-type(1) > DIV:nth-of-type(1) > DIV:nth-of-type(1) > DIV:nth-of-type(3) > DIV:nth-of-type(1) > DIV:nth-of-type(1) > DIV:nth-of-type(1) > DIV:nth-of-type(1) > DIV:nth-of-type(1) > DIV:nth-of-type(1) > DIV:nth-of-type(1) > DIV:nth-of-type(1) > DIV:nth-of-type(1) > DIV:nth-of-type(1) > DIV:nth-of-type(1) > H1:nth-of-type(1) | M7: 0 | N7: Offer3 | O7: To Be Confirmed | P7: Yes - offer template evidence | Q7: No evidence in inventory | R7: No evidence in inventory | S7: N/A - Target reporting source | T7: Yes | U7: Medium | V7: No | W7: Saved/inactive; retain for traceability and select if reactivated or confirmed business-critical. | X7: - | Y7: Not Started | Z7: No shared-location evidence found for this activity.
A8: COV-0004 | B8: To Be Confirmed | C8: 238801 | D8: [QD Test] XT Experience Demo | E8: xt | F8: approved | G8: To Be Confirmed | H8: target | I8: Experience A | J8: Location: 2625516 | K8: selector | L8: Location 0 - HTML > BODY > HEADER:nth-of-type(1) > DIV:nth-of-type(1) > DIV:nth-of-type(1) > DIV:nth-of-type(1) > DIV:nth-of-type(1) > DIV:nth-of-type(1) > IMG:nth-of-type(1) | M8: 0 | N8: - | O8: To Be Confirmed | P8: Yes - offer template evidence | Q8: No evidence in inventory | R8: No evidence in inventory | S8: N/A - Target reporting source | T8: Yes | U8: High | V8: Yes | W8: Approved/active activity; inventory risk High. | X8: TGT-RND-101 | Y8: Not Started | Z8: Shared-location indicator: up to 3 activity IDs use at least one same-named location.
A9: COV-0005 | B9: To Be Confirmed | C9: 238801 | D9: [QD Test] XT Experience Demo | E9: xt | F9: approved | G9: To Be Confirmed | H9: target | I9: Experience A | J9: Location: 2625516 | K9: selector | L9: Location 1 - HTML > BODY > NAV:nth-of-type(1) > DIV:nth-of-type(1) > A:nth-of-type(1) | M9: 0 | N9: - | O9: To Be Confirmed | P9: Yes - offer template evidence | Q9: No evidence in inventory | R9: No evidence in inventory | S9: N/A - Target reporting source | T9: Yes | U9: High | V9: Yes | W9: Approved/active activity; inventory risk High. | X9: TGT-RND-101 | Y9: Not Started | Z9: Shared-location indicator: up to 3 activity IDs use at least one same-named location.
A10: COV-0006 | B10: To Be Confirmed | C10: 238801 | D10: [QD Test] XT Experience Demo | E10: xt | F10: approved | G10: To Be Confirmed | H10: target | I10: Experience B | J10: Experience: 2625515 | Location: 2625516 | K10: selector | L10: Location 0 - HTML > BODY > HEADER:nth-of-type(1) > DIV:nth-of-type(1) > DIV:nth-of-type(1) > DIV:nth-of-type(1) > DIV:nth-of-type(1) > DIV:nth-of-type(1) > IMG:nth-of-type(1) | M10: 0 | N10: Offer2 | O10: To Be Confirmed | P10: Yes - offer template evidence | Q10: No evidence in inventory | R10: No evidence in inventory | S10: N/A - Target reporting source | T10: Yes | U10: High | V10: Yes | W10: Approved/active activity; inventory risk High. | X10: TGT-RND-101 | Y10: Not Started | Z10: Shared-location indicator: up to 3 activity IDs use at least one same-named location.
A11: COV-0007 | B11: To Be Confirmed | C11: 238801 | D11: [QD Test] XT Experience Demo | E11: xt | F11: approved | G11: To Be Confirmed | H11: target | I11: Experience B | J11: Experience: 2625515 | Location: 2625516 | K11: selector | L11: Location 1 - HTML > BODY > NAV:nth-of-type(1) > DIV:nth-of-type(1) > A:nth-of-type(1) | M11: 0 | N11: - | O11: To Be Confirmed | P11: Yes - offer template evidence | Q11: No evidence in inventory | R11: No evidence in inventory | S11: N/A - Target reporting source | T11: Yes | U11: High | V11: Yes | W11: Approved/active activity; inventory risk High. | X11: TGT-RND-101 | Y11: Not Started | Z11: Shared-location indicator: up to 3 activity IDs use at least one same-named location.
A12: COV-0008 | B12: To Be Confirmed | C12: 238801 | D12: [QD Test] XT Experience Demo | E12: xt | F12: approved | G12: To Be Confirmed | H12: target | I12: Experience C | J12: Experience: 2625532 | Location: 2625516 | K12: selector | L12: Location 0 - HTML > BODY > HEADER:nth-of-type(1) > DIV:nth-of-type(1) > DIV:nth-of-type(1) > DIV:nth-of-type(1) > DIV:nth-of-type(1) > DIV:nth-of-type(1) > IMG:nth-of-type(1) | M12: 0 | N12: Offer4 | O12: To Be Confirmed | P12: Yes - offer template evidence | Q12: No evidence in inventory | R12: No evidence in inventory | S12: N/A - Target reporting source | T12: Yes | U12: High | V12: Yes | W12: Approved/active activity; inventory risk High. | X12: TGT-RND-101 | Y12: Not Started | Z12: Shared-location indicator: up to 3 activity IDs use at least one same-named location.
A13: COV-0009 | B13: To Be Confirmed | C13: 238801 | D13: [QD Test] XT Experience Demo | E13: xt | F13: approved | G13: To Be Confirmed | H13: target | I13: Experience C | J13: Experience: 2625532 | Location: 2625516 | K13: selector | L13: Location 1 - HTML > BODY > NAV:nth-of-type(1) > DIV:nth-of-type(1) > A:nth-of-type(1) | M13: 0 | N13: Offer3 | O13: To Be Confirmed | P13: Yes - offer template evidence | Q13: No evidence in inventory | R13: No evidence in inventory | S13: N/A - Target reporting source | T13: Yes | U13: High | V13: Yes | W13: Approved/active activity; inventory risk High. | X13: TGT-RND-101 | Y13: Not Started | Z13: Shared-location indicator: up to 3 activity IDs use at least one same-named location.
A14: COV-0010 | B14: To Be Confirmed | C14: 265179 | D14: [Untitled Activity] Jan 14 2025, 14:52 | E14: xt | F14: saved | G14: To Be Confirmed | H14: target | I14: Experience A | J14: Location: 2961698 | K14: selector | L14: Location 0 - HTML > BODY > HEADER:nth-of-type(1) | M14: 0 | N14: Offer2 | O14: To Be Confirmed | P14: Yes - offer template evidence | Q14: No evidence in inventory | R14: No evidence in inventory | S14: N/A - Target reporting source | T14: Yes | U14: Medium | V14: No | W14: Saved/inactive; retain for traceability and select if reactivated or confirmed business-critical. | X14: - | Y14: Not Started | Z14: No shared-location evidence found for this activity.
A15: COV-0011 | B15: To Be Confirmed | C15: 265179 | D15: [Untitled Activity] Jan 14 2025, 14:52 | E15: xt | F15: saved | G15: To Be Confirmed | H15: target | I15: Experience A | J15: Location: 2961698 | K15: selector | L15: Location 1 - HTML > BODY > HEADER:nth-of-type(1) | M15: 0 | N15: Offer3 | O15: To Be Confirmed | P15: Yes - offer template evidence | Q15: No evidence in inventory | R15: No evidence in inventory | S15: N/A - Target reporting source | T15: Yes | U15: Medium | V15: No | W15: Saved/inactive; retain for traceability and select if reactivated or confirmed business-critical. | X15: - | Y15: Not Started | Z15: No shared-location evidence found for this activity.
A16: COV-0012 | B16: To Be Confirmed | C16: 319925 | D16: AB test activity | E16: ab | F16: approved | G16: To Be Confirmed | H16: target | I16: Experience A | J16: Location: 3628737 | K16: selector | L16: Location 1 - HTML > BODY > DIV:nth-of-type(1) > DIV:nth-of-type(1) > DIV:nth-of-type(1) > DIV:nth-of-type(2) > DIV:nth-of-type(1) > DIV:nth-of-type(1) > DIV:nth-of-type(1) > P:nth-of-type(2) > A:nth-of-type(1) | M16: 0 | N16: Default Content | O16: To Be Confirmed | P16: Yes - offer template evidence | Q16: No evidence in inventory | R16: No evidence in inventory | S16: N/A - Target reporting source | T16: Yes | U16: High | V16: Yes | W16: Approved/active activity; inventory risk High. | X16: TGT-RND-102 | Y16: Not Started | Z16: Shared-location indicator: up to 2 activity IDs use at least one same-named location.
... A25: COV-0021 | B25: To Be Confirmed | C25: 215656 | D25: AEP Accelerator Gender Based View | E25: xt | F25: approved | G25: To Be Confirmed | H25: target | I25: Experience B | J25: Experience: 2321342 | Location: 2321320 | K25: selector | L25: Location 3 - HTML > BODY > DIV.container:eq(0) > DIV.root:eq(0) > DIV.aem-Grid:eq(0) > DIV.responsivegrid:eq(0) > DIV.aem-Grid:eq(0) > DIV.we-carousel:eq(0) > DIV.cmp-carousel:eq(0) > DIV.cmp-carousel__content:eq(0) > DIV.cmp-carousel__item:eq(0) > DIV.teaser:eq(0) > DIV.cmp-teaser:eq(0) > DIV.cmp-teaser__image:eq(0) > DIV.cmp-image:eq(0) > IMG.cmp-image__image:eq(0) | M25: 0 | N25: Offer9 | O25: To Be Confirmed | P25: Yes - offer template evidence | Q25: No evidence in inventory | R25: No evidence in inventory | S25: N/A - Target reporting source | T25: Yes | U25: High | V25: Yes | W25: Approved/active activity; inventory risk High. | X25: TGT-RND-103 | Y25: Not Started | Z25: No shared-location evidence found for this activity.
A26: COV-0022 | B26: To Be Confirmed | C26: 319918 | D26: AP Test activity | E26: abt | F26: approved | G26: To Be Confirmed | H26: target | I26: - | J26: - | K26: - | L26: - | M26: - | N26: - | O26: To Be Confirmed | P26: No evidence in inventory | Q26: No evidence in inventory | R26: No evidence in inventory | S26: N/A - Target reporting source | T26: No evidence in inventory | U26: Medium | V26: Yes | W26: Approved/active activity; inventory risk Medium. | X26: TGT-RND-104 | Y26: Not Started | Z26: No shared-location evidence found for this activity. Placeholder activity detail row; route, location, and offer require confirmation.
A27: COV-0023 | B27: To Be Confirmed | C27: 229337 | D27: Arc First Test Activity | E27: ab | F27: saved | G27: To Be Confirmed | H27: target | I27: Experience A | J27: Location: 2531029 | K27: selector | L27: Location 0 - HTML > BODY > DIV:nth-of-type(1) > DIV:nth-of-type(1) > DIV:nth-of-type(1) > DIV:nth-of-type(2) > DIV:nth-of-type(1) > DIV:nth-of-type(1) > DIV:nth-of-type(1) > P:nth-of-type(2) > A:nth-of-type(1) | M27: 0 | N27: - | O27: To Be Confirmed | P27: Yes - offer template evidence | Q27: No evidence in inventory | R27: No evidence in inventory | S27: N/A - Target reporting source | T27: Yes | U27: Medium | V27: No | W27: Saved/inactive; retain for traceability and select if reactivated or confirmed business-critical. | X27: - | Y27: Not Started | Z27: No shared-location evidence found for this activity.
A28: COV-0024 | B28: To Be Confirmed | C28: 229337 | D28: Arc First Test Activity | E28: ab | F28: saved | G28: To Be Confirmed | H28: target | I28: Experience B | J28: Location: 2531029 | K28: selector | L28: Location 0 - HTML > BODY > DIV:nth-of-type(1) > DIV:nth-of-type(1) > DIV:nth-of-type(1) > DIV:nth-of-type(2) > DIV:nth-of-type(1) > DIV:nth-of-type(1) > DIV:nth-of-type(1) > P:nth-of-type(2) > A:nth-of-type(1) | M28: 0 | N28: Offer2 | O28: To Be Confirmed | P28: Yes - offer template evidence | Q28: No evidence in inventory | R28: No evidence in inventory | S28: N/A - Target reporting source | T28: Yes | U28: Medium | V28: No | W28: Saved/inactive; retain for traceability and select if reactivated or confirmed business-critical. | X28: - | Y28: Not Started | Z28: No shared-location evidence found for this activity.
A29: COV-0025 | B29: To Be Confirmed | C29: 276577 | D29: blogger A/B test | E29: ab | F29: approved | G29: To Be Confirmed | H29: target | I29: Experience A | J29: Location: 3113043 | K29: selector | L29: Location 0 - HTML > BODY > DIV:nth-of-type(1) > DIV:nth-of-type(1) > DIV:nth-of-type(1) > HEADER:nth-of-type(1) > DIV:nth-of-type(1) > DIV:nth-of-type(2) > DIV:nth-of-type(1) > DIV:nth-of-type(1) > DIV:nth-of-type(1) > DIV:nth-of-type(1) > H1:nth-of-type(1) | M29: 0 | N29: Offer2 | O29: To Be Confirmed | P29: Yes - offer template evidence | Q29: No evidence in inventory | R29: No evidence in inventory | S29: N/A - Target reporting source | T29: Yes | U29: High | V29: Yes | W29: Approved/active activity; inventory risk High. | X29: TGT-RND-105 | Y29: Not Started | Z29: No shared-location evidence found for this activity.
A30: COV-0026 | B30: To Be Confirmed | C30: 276577 | D30: blogger A/B test | E30: ab | F30: approved | G30: To Be Confirmed | H30: target | I30: Experience B | J30: Location: 3113043 | K30: selector | L30: Location 0 - HTML > BODY > DIV:nth-of-type(1) > DIV:nth-of-type(1) > DIV:nth-of-type(1) > HEADER:nth-of-type(1) > DIV:nth-of-type(1) > DIV:nth-of-type(2) > DIV:nth-of-type(1) > DIV:nth-of-type(1) > DIV:nth-of-type(1) > DIV:nth-of-type(1) > H1:nth-of-type(1) | M30: 0 | N30: Offer3 | O30: To Be Confirmed | P30: Yes - offer template evidence | Q30: No evidence in inventory | R30: No evidence in inventory | S30: N/A - Target reporting source | T30: Yes | U30: High | V30: Yes | W30: Approved/active activity; inventory risk High. | X30: TGT-RND-105 | Y30: Not Started | Z30: No shared-location evidence found for this activity.
A31: COV-0027 | B31: To Be Confirmed | C31: 320120 | D31: CAP Gender Personalization | E31: xt | F31: saved | G31: To Be Confirmed | H31: target | I31: Experience B | J31: Experience: 3631673 | Location: 3631680 | K31: selector | L31: Location 1 - HTML > BODY > SECTION:nth-of-type(1) > DIV:nth-of-type(1) > H1:nth-of-type(1) | M31: 0 | N31: Offer 18 | O31: To Be Confirmed | P31: Yes - offer template evidence | Q31: No evidence in inventory | R31: No evidence in inventory | S31: N/A - Target reporting source | T31: Yes | U31: Medium | V31: No | W31: Saved/inactive; retain for traceability and select if reactivated or confirmed business-critical. | X31: - | Y31: Not Started | Z31: Shared-location indicator: up to 2 activity IDs use at least one same-named location.
A32: COV-0028 | B32: To Be Confirmed | C32: 320120 | D32: CAP Gender Personalization | E32: xt | F32: saved | G32: To Be Confirmed | H32: target | I32: Experience D | J32: Experience: 3635114 | Location: 3631680 | K32: selector | L32: Location 1 - HTML > BODY > SECTION:nth-of-type(1) > DIV:nth-of-type(1) > H1:nth-of-type(1) | M32: 0 | N32: Offer 19 | O32: To Be Confirmed | P32: Yes - offer template evidence | Q32: No evidence in inventory | R32: No evidence in inventory | S32: N/A - Target reporting source | T32: Yes | U32: Medium | V32: No | W32: Saved/inactive; retain for traceability and select if reactivated or confirmed business-critical. | X32: - | Y32: Not Started | Z32: Shared-location indicator: up to 2 activity IDs use at least one same-named location.
A33: COV-0029 | B33: To Be Confirmed | C33: 319723 | D33: CAP POC Test1 | E33: xt | F33: saved | G33: To Be Confirmed | H33: target | I33: Experience A | J33: Location: 3625512 | K33: selector | L33: Location 1 - HTML > BODY > SECTION:nth-of-type(1) > DIV:nth-of-type(1) > H1:nth-of-type(1) | M33: 0 | N33: Offer 496 | O33: To Be Confirmed | P33: Yes - offer template evidence | Q33: No evidence in inventory | R33: No evidence in inventory | S33: N/A - Target reporting source | T33: Yes | U33: Medium | V33: No | W33: Saved/inactive; retain for traceability and select if reactivated or confirmed business-critical. | X33: - | Y33: Not Started | Z33: Shared-location indicator: up to 2 activity IDs use at least one same-named location.
A34: COV-0030 | B34: To Be Confirmed | C34: 319723 | D34: CAP POC Test1 | E34: xt | F34: saved | G34: To Be Confirmed | H34: target | I34: Experience A | J34: Location: 3625512 | K34: selector | L34: Location 10 - HTML > BODY > SECTION:nth-of-type(1) > DIV:nth-of-type(1) > H1:nth-of-type(1) | M34: 0 | N34: Offer 496 | O34: To Be Confirmed | P34: Yes - offer template evidence | Q34: No evidence in inventory | R34: No evidence in inventory | S34: N/A - Target reporting source | T34: Yes | U34: Medium | V34: No | W34: Saved/inactive; retain for traceability and select if reactivated or confirmed business-critical. | X34: - | Y34: Not Started | Z34: Shared-location indicator: up to 2 activity IDs use at least one same-named location.
A35: COV-0031 | B35: To Be Confirmed | C35: 319723 | D35: CAP POC Test1 | E35: xt | F35: saved | G35: To Be Confirmed | H35: target | I35: Experience A | J35: Location: 3625512 | K35: selector | L35: Location 16 - HTML > BODY > SECTION:nth-of-type(1) > DIV:nth-of-type(1) > H2:nth-of-type(1) | M35: 0 | N35: Offer 524 | O35: To Be Confirmed | P35: Yes - offer template evidence | Q35: No evidence in inventory | R35: No evidence in inventory | S35: N/A - Target reporting source | T35: Yes | U35: Medium | V35: No | W35: Saved/inactive; retain for traceability and select if reactivated or confirmed business-critical. | X35: - | Y35: Not Started | Z35: Shared-location indicator: up to 2 activity IDs use at least one same-named location.
A36: COV-0032 | B36: To Be Confirmed | C36: 319723 | D36: CAP POC Test1 | E36: xt | F36: saved | G36: To Be Confirmed | H36: target | I36: Experience A | J36: Location: 3625512 | K36: selector | L36: Location 22 - HTML > BODY > SECTION:nth-of-type(1) > DIV:nth-of-type(1) > H6:nth-of-type(1) | M36: 0 | N36: Offer 530 | O36: To Be Confirmed | P36: Yes - offer template evidence | Q36: No evidence in inventory | R36: No evidence in inventory | S36: N/A - Target reporting source | T36: Yes | U36: Medium | V36: No | W36: Saved/inactive; retain for traceability and select if reactivated or confirmed business-critical. | X36: - | Y36: Not Started | Z36: Shared-location indicator: up to 2 activity IDs use at least one same-named location.
A37: COV-0033 | B37: To Be Confirmed | C37: 319723 | D37: CAP POC Test1 | E37: xt | F37: saved | G37: To Be Confirmed | H37: target | I37: Experience A | J37: Location: 3625512 | K37: selector | L37: Location 4 - HTML > BODY > SECTION:nth-of-type(1) | M37: 0 | N37: Offer 526 | O37: To Be Confirmed | P37: Yes - offer template evidence | Q37: No evidence in inventory | R37: No evidence in inventory | S37: N/A - Target reporting source | T37: Yes | U37: Medium | V37: No | W37: Saved/inactive; retain for traceability and select if reactivated or confirmed business-critical. | X37: - | Y37: Not Started | Z37: Shared-location indicator: up to 2 activity IDs use at least one same-named location.
A38: COV-0034 | B38: To Be Confirmed | C38: 319723 | D38: CAP POC Test1 | E38: xt | F38: saved | G38: To Be Confirmed | H38: target | I38: Experience A | J38: Location: 3625512 | K38: selector | L38: Location 9 - HTML > BODY > SECTION:nth-of-type(1) > DIV:nth-of-type(1) > H1:nth-of-type(1) | M38: 0 | N38: Offer 496 | O38: To Be Confirmed | P38: Yes - offer template evidence | Q38: No evidence in inventory | R38: No evidence in inventory | S38: N/A - Target reporting source | T38: Yes | U38: Medium | V38: No | W38: Saved/inactive; retain for traceability and select if reactivated or confirmed business-critical. | X38: - | Y38: Not Started | Z38: Shared-location indicator: up to 2 activity IDs use at least one same-named location.
... A146: COV-0142 | B146: To Be Confirmed | C146: 277464 | D146: Naln luma A/B test | E146: ab | F146: saved | G146: To Be Confirmed | H146: target | I146: Experience B | J146: Location: 3123894 | K146: selector | L146: Location 2 - HTML > BODY > DIV:nth-of-type(1) > DIV:nth-of-type(1) > DIV:nth-of-type(1) > DIV:nth-of-type(2) > DIV:nth-of-type(1) > DIV:nth-of-type(1) > DIV:nth-of-type(1) > P:nth-of-type(2) > A:nth-of-type(1) | M146: 0 | N146: Offer4 | O146: To Be Confirmed | P146: Yes - offer template evidence | Q146: No evidence in inventory | R146: No evidence in inventory | S146: N/A - Target reporting source | T146: Yes | U146: Medium | V146: No | W146: Saved/inactive; retain for traceability and select if reactivated or confirmed business-critical. | X146: - | Y146: Not Started | Z146: Shared-location indicator: up to 3 activity IDs use at least one same-named location.
A147: COV-0143 | B147: To Be Confirmed | C147: 277466 | D147: naln luma MVT | E147: mvt | F147: saved | G147: To Be Confirmed | H147: target | I147: - | J147: - | K147: - | L147: - | M147: - | N147: - | O147: To Be Confirmed | P147: No evidence in inventory | Q147: No evidence in inventory | R147: No evidence in inventory | S147: N/A - Target reporting source | T147: No evidence in inventory | U147: Low | V147: No | W147: Saved/inactive; retain for traceability and select if reactivated or confirmed business-critical. | X147: - | Y147: Not Started | Z147: No shared-location evidence found for this activity. Placeholder activity detail row; route, location, and offer require confirmation.
A148: COV-0144 | B148: To Be Confirmed | C148: 277465 | D148: Naln Luma XT | E148: xt | F148: saved | G148: To Be Confirmed | H148: target | I148: Experience A | J148: Experience: 3123899 | Location: 3123901 | K148: selector | L148: Location 0 - HTML > BODY > DIV:nth-of-type(1) > DIV:nth-of-type(1) > DIV:nth-of-type(1) > DIV:nth-of-type(2) > DIV:nth-of-type(1) > DIV:nth-of-type(1) > DIV:nth-of-type(1) > P:nth-of-type(1) | M148: 0 | N148: Offer2 | O148: To Be Confirmed | P148: Yes - offer template evidence | Q148: No evidence in inventory | R148: No evidence in inventory | S148: N/A - Target reporting source | T148: Yes | U148: Medium | V148: No | W148: Saved/inactive; retain for traceability and select if reactivated or confirmed business-critical. | X148: - | Y148: Not Started | Z148: Shared-location indicator: up to 3 activity IDs use at least one same-named location.
A149: COV-0145 | B149: To Be Confirmed | C149: 277465 | D149: Naln Luma XT | E149: xt | F149: saved | G149: To Be Confirmed | H149: target | I149: Experience B | J149: Experience: 3123900 | Location: 3123901 | K149: selector | L149: Location 0 - HTML > BODY > DIV:nth-of-type(1) > DIV:nth-of-type(1) > DIV:nth-of-type(1) > DIV:nth-of-type(2) > DIV:nth-of-type(1) > DIV:nth-of-type(1) > DIV:nth-of-type(1) > P:nth-of-type(1) | M149: 0 | N149: Offer3 | O149: To Be Confirmed | P149: Yes - offer template evidence | Q149: No evidence in inventory | R149: No evidence in inventory | S149: N/A - Target reporting source | T149: Yes | U149: Medium | V149: No | W149: Saved/inactive; retain for traceability and select if reactivated or confirmed business-critical. | X149: - | Y149: Not Started | Z149: Shared-location indicator: up to 3 activity IDs use at least one same-named location.
A150: COV-0146 | B150: To Be Confirmed | C150: 313102 | D150: Next POC | E150: ab | F150: saved | G150: To Be Confirmed | H150: target | I150: Experience A | J150: Location: 3550328 | K150: selector | L150: emptyNoSelector - emptyNoSelector | M150: 0 | N150: Default Content | O150: To Be Confirmed | P150: No evidence in inventory | Q150: No evidence in inventory | R150: No evidence in inventory | S150: N/A - Target reporting source | T150: Yes | U150: Medium | V150: No | W150: Saved/inactive; retain for traceability and select if reactivated or confirmed business-critical. | X150: - | Y150: Not Started | Z150: Shared-location indicator: up to 2 activity IDs use at least one same-named location.
A151: COV-0147 | B151: To Be Confirmed | C151: 313102 | D151: Next POC | E151: ab | F151: saved | G151: To Be Confirmed | H151: target | I151: Experience B | J151: Location: 3550328 | K151: selector | L151: emptyNoSelector - emptyNoSelector | M151: 0 | N151: Default Content | O151: To Be Confirmed | P151: No evidence in inventory | Q151: No evidence in inventory | R151: No evidence in inventory | S151: N/A - Target reporting source | T151: Yes | U151: Medium | V151: No | W151: Saved/inactive; retain for traceability and select if reactivated or confirmed business-critical. | X151: - | Y151: Not Started | Z151: Shared-location indicator: up to 2 activity IDs use at least one same-named location.
A152: COV-0148 | B152: To Be Confirmed | C152: 292739 | D152: okta.com | E152: xt | F152: approved | G152: To Be Confirmed | H152: target | I152: Experience A | J152: Experience: 3317210 | K152: mbox | L152: launch-trigger-mbox | M152: 807069 | N152: test_111_html | O152: To Be Confirmed | P152: Yes - script evidence | Q152: No evidence in inventory | R152: No evidence in inventory | S152: N/A - Target reporting source | T152: Yes | U152: High | V152: Yes | W152: Approved/active activity; inventory risk High. | X152: TGT-RND-115 | Y152: Not Started | Z152: No shared-location evidence found for this activity.
A153: COV-0149 | B153: To Be Confirmed | C153: 292589 | D153: okta.com test2 | E153: ab | F153: approved | G153: To Be Confirmed | H153: target | I153: Experience A | J153: Location: 3315731,3318542 | K153: selector | L153: Location 3 - HTML > BODY > DIV:nth-of-type(1) > DIV:nth-of-type(1) > DIV:nth-of-type(1) > DIV:nth-of-type(2) > DIV:nth-of-type(1) > DIV:nth-of-type(1) > DIV:nth-of-type(1) > SECTION:nth-of-type(1) > DIV:nth-of-type(1) > DIV:nth-of-type(1) > DIV:nth-of-type(1) > DIV:nth-of-type(1) > H1:nth-of-type(1) | M153: 0 | N153: Offer 7 | O153: To Be Confirmed | P153: Yes - offer template evidence | Q153: Yes | R153: No evidence in inventory | S153: N/A - Target reporting source | T153: Yes | U153: High | V153: Yes | W153: Approved/active activity; inventory risk High. | X153: TGT-RND-116 | Y153: Not Started | Z153: No shared-location evidence found for this activity.
A154: COV-0150 | B154: To Be Confirmed | C154: 292589 | D154: okta.com test2 | E154: ab | F154: approved | G154: To Be Confirmed | H154: target | I154: Experience B | J154: Location: 3315731,3318542 | K154: selector | L154: Location 3 - HTML > BODY > DIV:nth-of-type(1) > DIV:nth-of-type(1) > DIV:nth-of-type(1) > DIV:nth-of-type(2) > DIV:nth-of-type(1) > DIV:nth-of-type(1) > DIV:nth-of-type(1) > SECTION:nth-of-type(1) > DIV:nth-of-type(1) > DIV:nth-of-type(1) > DIV:nth-of-type(1) > DIV:nth-of-type(1) > H1:nth-of-type(1) | M154: 0 | N154: Offer 6 | O154: To Be Confirmed | P154: Yes - offer template evidence | Q154: Yes | R154: No evidence in inventory | S154: N/A - Target reporting source | T154: Yes | U154: High | V154: Yes | W154: Approved/active activity; inventory risk High. | X154: TGT-RND-116 | Y154: Not Started | Z154: No shared-location evidence found for this activity.
A155: COV-0151 | B155: To Be Confirmed | C155: 245616 | D155: Oliver TGA AB Test | E155: ab | F155: approved | G155: To Be Confirmed | H155: target | I155: Experience A | J155: Location: 2717218 | K155: selector | L155: Location 0 - HEAD | M155: 0 | N155: Offer2 | O155: To Be Confirmed | P155: Yes - offer template evidence | Q155: No evidence in inventory | R155: No evidence in inventory | S155: N/A - Target reporting source | T155: Yes | U155: High | V155: Yes | W155: Approved/active activity; inventory risk High. | X155: TGT-RND-117 | Y155: Not Started | Z155: No shared-location evidence found for this activity.
A156: COV-0152 | B156: To Be Confirmed | C156: 245616 | D156: Oliver TGA AB Test | E156: ab | F156: approved | G156: To Be Confirmed | H156: target | I156: Experience B | J156: Location: 2717218 | K156: selector | L156: Location 0 - HEAD | M156: 0 | N156: Offer3 | O156: To Be Confirmed | P156: Yes - offer template evidence | Q156: No evidence in inventory | R156: No evidence in inventory | S156: N/A - Target reporting source | T156: Yes | U156: High | V156: Yes | W156: Approved/active activity; inventory risk High. | X156: TGT-RND-117 | Y156: Not Started | Z156: No shared-location evidence found for this activity.
...

Sheet Test Case Master
A1: Test Case Master
A2: 30 generic migration controls plus 43 activity-specific rows for all approved activities. Replace To Be Confirmed fields before execution and link every failure to a defect.
A4: Test Case ID | B4: Test Scenario | C4: Test Category | D4: Business Group | E4: Activity ID | F4: Activity Name | G4: Experience | H4: Reporting Source | I4: Environment | J4: Page/Route | K4: Preconditions | L4: Test Data | M4: Execution Steps | N4: Expected Target Request | O4: Expected Parameters | P4: Expected Audience Result | Q4: Expected Proposition | R4: Expected Rendering | S4: Expected Reporting | T4: Actual Result | U4: Status | V4: Severity if Failed | W4: Defect ID | X4: Evidence Link | Y4: Tester | Z4: Execution Date | AA4: Retest Status | AB4: Approver | AC4: Comments
A5: TGT-REQ-001 | B5: Web SDK library loads successfully | C5: Target Request | D5: To Be Confirmed | E5: To Be Confirmed | F5: Generic migration control | G5: To Be Confirmed | H5: Target / Analytics as applicable | I5: To Be Confirmed | J5: To Be Confirmed | K5: Migration build deployed; required access, test data, consent state, and identity state are available. | L5: To Be Confirmed | M5: Load the page in a clean profile; inspect network and console; confirm one supported Web SDK instance. | N5: Library loads without error and is available before the intended decision event. | O5: Validate applicable inventory and mapping dependencies. | P5: Validate qualified and non-qualified behavior where applicable. | Q5: Validate the applicable activity and experience identifiers where a decision is expected. | R5: Validate visible rendering only where the scenario produces an experience. | S5: Validate applicable reporting behavior and absence of duplicate calls. | U5: Not Started | AA5: Not Started | AC5: Generic migration test; replace To Be Confirmed fields before execution.
A6: TGT-REQ-002 | B6: Correct datastream is used | C6: Target Request | D6: To Be Confirmed | E6: To Be Confirmed | F6: Generic migration control | G6: To Be Confirmed | H6: Target / Analytics as applicable | I6: To Be Confirmed | J6: To Be Confirmed | K6: Migration build deployed; required access, test data, consent state, and identity state are available. | L6: To Be Confirmed | M6: Trigger the page event; inspect the Edge request and environment metadata; compare with the approved environment matrix. | N6: Request is sent through the approved environment-specific datastream. | O6: Validate applicable inventory and mapping dependencies. | P6: Validate qualified and non-qualified behavior where applicable. | Q6: Validate the applicable activity and experience identifiers where a decision is expected. | R6: Validate visible rendering only where the scenario produces an experience. | S6: Validate applicable reporting behavior and absence of duplicate calls. | U6: Not Started | AA6: Not Started | AC6: Generic migration test; replace To Be Confirmed fields before execution.
A7: TGT-REQ-003 | B7: Initial page-view event is sent once | C7: Target Request | D7: To Be Confirmed | E7: To Be Confirmed | F7: Generic migration control | G7: To Be Confirmed | H7: Target / Analytics as applicable | I7: To Be Confirmed | J7: To Be Confirmed | K7: Migration build deployed; required access, test data, consent state, and identity state are available. | L7: To Be Confirmed | M7: Load the page once; filter Edge and Analytics requests; count the defined initial event and associated Target decision. | N7: Exactly one initial event and one intended decision request are sent. | O7: Validate applicable inventory and mapping dependencies. | P7: Validate qualified and non-qualified behavior where applicable. | Q7: Validate the applicable activity and experience identifiers where a decision is expected. | R7: Validate visible rendering only where the scenario produces an experience. | S7: Validate applicable reporting behavior and absence of duplicate calls. | U7: Not Started | AA7: Not Started | AC7: Generic migration test; replace To Be Confirmed fields before execution.
A8: TGT-SPA-001 | B8: SPA route event is sent once | C8: SPA | D8: To Be Confirmed | E8: To Be Confirmed | F8: Generic migration control | G8: To Be Confirmed | H8: Target / Analytics as applicable | I8: To Be Confirmed | J8: To Be Confirmed | K8: Migration build deployed; required access, test data, consent state, and identity state are available. | L8: To Be Confirmed | M8: Navigate internally to a qualifying route; inspect route context and request count without a full reload. | N8: Exactly one route event is sent with the correct route context. | O8: Validate applicable inventory and mapping dependencies. | P8: Validate qualified and non-qualified behavior where applicable. | Q8: Validate the applicable activity and experience identifiers where a decision is expected. | R8: Exactly one route event is sent with the correct route context. | S8: Validate applicable reporting behavior and absence of duplicate calls. | U8: Not Started | AA8: Not Started | AC8: Generic migration test; replace To Be Confirmed fields before execution.
A9: TGT-PAR-001 | B9: Required mbox parameters are present | C9: Parameter | D9: To Be Confirmed | E9: To Be Confirmed | F9: Generic migration control | G9: To Be Confirmed | H9: Target / Analytics as applicable | I9: To Be Confirmed | J9: To Be Confirmed | K9: Migration build deployed; required access, test data, consent state, and identity state are available. | L9: To Be Confirmed | M9: Use the parameter mapping sheet; inspect the actual Target data in the Edge request. | N9: Validate the request applicable to the scenario; no environment-specific value is available. | O9: Every required mbox parameter has the expected name, value, type, and timing. | P9: Validate qualified and non-qualified behavior where applicable. | Q9: Validate the applicable activity and experience identifiers where a decision is expected. | R9: Validate visible rendering only where the scenario produces an experience. | S9: Validate applicable reporting behavior and absence of duplicate calls. | U9: Not Started | AA9: Not Started | AC9: Generic migration test; replace To Be Confirmed fields before execution.
A10: TGT-PAR-002 | B10: Required profile parameters are present | C10: Parameter | D10: To Be Confirmed | E10: To Be Confirmed | F10: Generic migration control | G10: To Be Confirmed | H10: Target / Analytics as applicable | I10: To Be Confirmed | J10: To Be Confirmed | K10: Migration build deployed; required access, test data, consent state, and identity state are available. | L10: To Be Confirmed | M10: Use a controlled visitor; inspect the request and subsequent qualification behavior. | N10: Validate the request applicable to the scenario; no environment-specific value is available. | O10: Required profile parameters are available before qualification and persist as designed. | P10: Validate qualified and non-qualified behavior where applicable. | Q10: Validate the applicable activity and experience identifiers where a decision is expected. | R10: Validate visible rendering only where the scenario produces an experience. | S10: Validate applicable reporting behavior and absence of duplicate calls. | U10: Not Started | AA10: Not Started | AC10: Generic migration test; replace To Be Confirmed fields before execution.
A11: TGT-PAR-003 | B11: Parameter values match the legacy implementation | C11: Parameter | D11: To Be Confirmed | E11: To Be Confirmed | F11: Generic migration control | G11: To Be Confirmed | H11: Target / Analytics as applicable | I11: To Be Confirmed | J11: To Be Confirmed | K11: Migration build deployed; required access, test data, consent state, and identity state are available. | L11: To Be Confirmed | M11: Execute matched legacy and Web SDK scenarios; compare transmitted values and timing. | N11: Validate the request applicable to the scenario; no environment-specific value is available. | O11: Values match or an approved intentional mapping difference is documented. | P11: Validate qualified and non-qualified behavior where applicable. | Q11: Validate the applicable activity and experience identifiers where a decision is expected. | R11: Validate visible rendering only where the scenario produces an experience. | S11: Validate applicable reporting behavior and absence of duplicate calls. | U11: Not Started | AA11: Not Started | AC11: Generic migration test; replace To Be Confirmed fields before execution.
A12: TGT-IDN-001 | B12: Identity is available before Target decisioning | C12: Identity | D12: To Be Confirmed | E12: To Be Confirmed | F12: Generic migration control | G12: To Be Confirmed | H12: Target / Analytics as applicable | I12: To Be Confirmed | J12: To Be Confirmed | K12: Migration build deployed; required access, test data, consent state, and identity state are available. | L12: To Be Confirmed | M12: Load or authenticate using masked test identity; inspect identityMap and request sequence. | N12: Required identity namespaces are present before dependent decisioning. | O12: Required identity namespaces are present before dependent decisioning. | P12: Validate qualified and non-qualified behavior where applicable. | Q12: Validate the applicable activity and experience identifiers where a decision is expected. | R12: Validate visible rendering only where the scenario produces an experience. | S12: Validate applicable reporting behavior and absence of duplicate calls. | U12: Not Started | AA12: Not Started | AC12: Generic migration test; replace To Be Confirmed fields before execution.
A13: TGT-PRP-001 | B13: Correct activity is returned | C13: Proposition | D13: To Be Confirmed | E13: To Be Confirmed | F13: Generic migration control | G13: To Be Confirmed | H13: Target / Analytics as applicable | I13: To Be Confirmed | J13: To Be Confirmed | K13: Migration build deployed; required access, test data, consent state, and identity state are available. | L13: To Be Confirmed | M13: Meet the selected activity conditions; inspect the returned proposition identifiers. | N13: Validate the request applicable to the scenario; no environment-specific value is available. | O13: Validate applicable inventory and mapping dependencies. | P13: Validate qualified and non-qualified behavior where applicable. | Q13: The expected activity ID is returned for the qualified visitor. | R13: Validate visible rendering only where the scenario produces an experience. | S13: Validate applicable reporting behavior and absence of duplicate calls. | U13: Not Started | AA13: Not Started | AC13: Generic migration test; replace To Be Confirmed fields before execution.
A14: TGT-PRP-002 | B14: Correct experience is returned | C14: Proposition | D14: To Be Confirmed | E14: To Be Confirmed | F14: Generic migration control | G14: To Be Confirmed | H14: Target / Analytics as applicable | I14: To Be Confirmed | J14: To Be Confirmed | K14: Migration build deployed; required access, test data, consent state, and identity state are available. | L14: To Be Confirmed | M14: Force or qualify for the expected experience; inspect response and visible result. | N14: Validate the request applicable to the scenario; no environment-specific value is available. | O14: Validate applicable inventory and mapping dependencies. | P14: Validate qualified and non-qualified behavior where applicable. | Q14: The expected experience is returned and identified separately from the default. | R14: Validate visible rendering only where the scenario produces an experience. | S14: Validate applicable reporting behavior and absence of duplicate calls. | U14: Not Started | AA14: Not Started | AC14: Generic migration test; replace To Be Confirmed fields before execution.
A15: TGT-AUD-001 | B15: Default experience is returned for a non-qualified visitor | C15: Audience | D15: To Be Confirmed | E15: To Be Confirmed | F15: Generic migration control | G15: To Be Confirmed | H15: Target / Analytics as applicable | I15: To Be Confirmed | J15: To Be Confirmed | K15: Migration build deployed; required access, test data, consent state, and identity state are available. | L15: To Be Confirmed | M15: Use negative test data; clear profile state where required; request the decision. | N15: Validate the request applicable to the scenario; no environment-specific value is available. | O15: Validate applicable inventory and mapping dependencies. | P15: Visitor does not receive the personalized experience and receives the configured default/no offer. | Q15: Validate the applicable activity and experience identifiers where a decision is expected. | R15: Validate visible rendering only where the scenario produces an experience. | S15: Validate applicable reporting behavior and absence of duplicate calls. | U15: Not Started | AA15: Not Started | AC15: Generic migration test; replace To Be Confirmed fields before execution.
A16: TGT-AUD-002 | B16: Personalized experience is returned for a qualified visitor | C16: Audience | D16: To Be Confirmed | E16: To Be Confirmed | F16: Generic migration control | G16: To Be Confirmed | H16: Target / Analytics as applicable | I16: To Be Confirmed | J16: To Be Confirmed | K16: Migration build deployed; required access, test data, consent state, and identity state are available. | L16: To Be Confirmed | M16: Use positive test data matching the complete audience rule; request the decision. | N16: Validate the request applicable to the scenario; no environment-specific value is available. | O16: Validate applicable inventory and mapping dependencies. | P16: Visitor qualifies and receives the expected personalized experience. | Q16: Validate the applicable activity and experience identifiers where a decision is expected. | R16: Validate visible rendering only where the scenario produces an experience. | S16: Validate applicable reporting behavior and absence of duplicate calls. | U16: Not Started | AA16: Not Started | AC16: Generic migration test; replace To Be Confirmed fields before execution.
... A34: TGT-PRD-001 | B34: Production smoke test passes | C34: Production Smoke | D34: To Be Confirmed | E34: To Be Confirmed | F34: Generic migration control | G34: To Be Confirmed | H34: Target / Analytics as applicable | I34: To Be Confirmed | J34: To Be Confirmed | K34: Migration build deployed; required access, test data, consent state, and identity state are available. | L34: To Be Confirmed | M34: After release, execute the approved smoke set and validate request, parameters, decision, render, reporting, errors, and duplication. | N34: Validate the request applicable to the scenario; no environment-specific value is available. | O34: Validate applicable inventory and mapping dependencies. | P34: Validate qualified and non-qualified behavior where applicable. | Q34: Validate the applicable activity and experience identifiers where a decision is expected. | R34: Critical production checks pass and monitoring begins with no release-stopping issue. | S34: Critical production checks pass and monitoring begins with no release-stopping issue. | U34: Not Started | AA34: Not Started | AC34: Generic migration test; replace To Be Confirmed fields before execution.
A35: TGT-RND-101 | B35: Activity-specific end-to-end qualification, proposition, rendering, and reporting validation | C35: Rendering | D35: To Be Confirmed | E35: 238801 | F35: [QD Test] XT Experience Demo | G35: Experience A, Experience B, Experience C | H35: target | I35: To Be Confirmed | J35: To Be Confirmed | K35: Approved activity; Target QA URL, route, positive/negative audience data, consent state, and identity state are available. | L35: To Be Confirmed | M35: Open the page/route with positive test data; inspect Web SDK request and Target response; confirm visible offer; execute applicable interaction/conversion; validate reporting; repeat with negative data and on route revisit. | N35: One intended Target decision for location type(s) selector and location(s) Location 0 - HTML > BODY > HEADER:nth-of-type(1) > DIV:nth-of-type(1) > DIV:nth-of-type(1) > DIV:nth-of-type(1) > DIV:nth-of-type(1) > DIV:nth-of-type(1) > IMG:nth-of-type(1), Location 1 - HTML > BODY > NAV:nth-of-type(1) > DIV:nth-of-type(1) > A:nth-of-type(1). | O35: Inventory-linked audience parameters: country, domain, path. Validate exact names, values, types, and timing. | P35: Validate positive and negative qualification for audience ID(s) 2625515, 2625516, 2625532. | Q35: Returned proposition identifies activity 238801 and configured experience(s): Experience A, Experience B, Experience C. | R35: Render configured offer(s) 0 - Offer2, Offer3, Offer4 in location(s) Location 0 - HTML > BODY > HEADER:nth-of-type(1) > DIV:nth-of-type(1) > DIV:nth-of-type(1) > DIV:nth-of-type(1) > DIV:nth-of-type(1) > DIV:nth-of-type(1) > IMG:nth-of-type(1), Location 1 - HTML > BODY > NAV:nth-of-type(1) > DIV:nth-of-type(1) > A:nth-of-type(1) once, without stale or duplicate content. | S35: Validate Target metric(s) MY PRIMARY GOAL; action count_once; location mbox / target-global-mbox; success event mbox_shown. | U35: Not Started | AA35: Not Started | AC35: Inventory-derived planning row. Risk: High. Custom code: Yes - offer template evidence. Shared-location activity count indicator: 3.
A36: TGT-RND-102 | B36: Activity-specific end-to-end qualification, proposition, rendering, and reporting validation | C36: Rendering | D36: To Be Confirmed | E36: 319925 | F36: AB test activity | G36: Experience A, Experience B | H36: target | I36: To Be Confirmed | J36: To Be Confirmed | K36: Approved activity; Target QA URL, route, positive/negative audience data, consent state, and identity state are available. | L36: To Be Confirmed | M36: Open the page/route with positive test data; inspect Web SDK request and Target response; confirm visible offer; execute applicable interaction/conversion; validate reporting; repeat with negative data and on route revisit. | N36: One intended Target decision for location type(s) selector and location(s) Location 1 - HTML > BODY > DIV:nth-of-type(1) > DIV:nth-of-type(1) > DIV:nth-of-type(1) > DIV:nth-of-type(2) > DIV:nth-of-type(1) > DIV:nth-of-type(1) > DIV:nth-of-type(1) > P:nth-of-type(2) > A:nth-of-type(1). | O36: Inventory-linked audience parameters: domain, path. Validate exact names, values, types, and timing. | P36: Validate positive and negative qualification for audience ID(s) 3628737. | Q36: Returned proposition identifies activity 319925 and configured experience(s): Experience A, Experience B. | R36: Render configured offer(s) 0 - Default Content, Offer 2 in location(s) Location 1 - HTML > BODY > DIV:nth-of-type(1) > DIV:nth-of-type(1) > DIV:nth-of-type(1) > DIV:nth-of-type(2) > DIV:nth-of-type(1) > DIV:nth-of-type(1) > DIV:nth-of-type(1) > P:nth-of-type(2) > A:nth-of-type(1) once, without stale or duplicate content. | S36: Validate Target metric(s) ADDITIONAL GOAL 1,ADDITIONAL GOAL 2,MY PRIMARY GOAL; action count_once; location mbox / target-global-mbox1,target-global-mbox; success event mbox_shown. | U36: Not Started | AA36: Not Started | AC36: Inventory-derived planning row. Risk: High. Custom code: Yes - offer template evidence. Shared-location activity count indicator: 2.
A37: TGT-RND-103 | B37: Activity-specific end-to-end qualification, proposition, rendering, and reporting validation | C37: Rendering | D37: To Be Confirmed | E37: 215656 | F37: AEP Accelerator Gender Based View | G37: Experience A, Experience B | H37: target | I37: To Be Confirmed | J37: To Be Confirmed | K37: Approved activity; Target QA URL, route, positive/negative audience data, consent state, and identity state are available. | L37: To Be Confirmed | M37: Open the page/route with positive test data; inspect Web SDK request and Target response; confirm visible offer; execute applicable interaction/conversion; validate reporting; repeat with negative data and on route revisit. | N37: One intended Target decision for location type(s) selector and location(s) Location 0 - HTML > BODY > DIV.container:eq(0) > DIV.root:eq(0) > DIV.aem-Grid:eq(0) > DIV.responsivegrid:eq(0) > DIV.aem-Grid:eq(0) > DIV.we-carousel:eq(0) > DIV.cmp-carousel:eq(0) > DIV.cmp-carousel__content:eq(0) > DIV.cmp-carousel__item:eq(0) > DIV.teaser:eq(0) > DIV.cmp-teaser:eq(0) > DIV.cmp-teaser__content:eq(0) > DIV.cmp-teaser__action-container:eq(0) > A.cmp-teaser__action-link:eq(0), Location 1 - HTML > BODY > DIV.container:eq(0) > DIV.root:eq(0) > DIV.aem-Grid:eq(0) > DIV.responsivegrid:eq(0) > DIV.aem-Grid:eq(0) > DIV.we-carousel:eq(0) > DIV.cmp-carousel:eq(0) > DIV.cmp-carousel__content:eq(0) > DIV.cmp-carousel__item:eq(0) > DIV.teaser:eq(0) > DIV.cmp-teaser:eq(0) > DIV.cmp-teaser__content:eq(0) > DIV.cmp-teaser__action-container:eq(0) > A.cmp-teaser__action-link:eq(0), Location 2 - HTML > BODY > DIV.container:eq(0) > DIV.root:eq(0) > DIV.aem-Grid:eq(0) > DIV.responsivegr.... | O37: Inventory-linked audience parameters: domain, path. Validate exact names, values, types, and timing. | P37: Validate positive and negative qualification for audience ID(s) 2321320, 2321342, 2321343. | Q37: Returned proposition identifies activity 215656 and configured experience(s): Experience A, Experience B. | R37: Render configured offer(s) 0 - Offer2, Offer3, Offer4, Offer5, Offer6, Offer7, Offer8, Offer9 in location(s) Location 0 - HTML > BODY > DIV.container:eq(0) > DIV.root:eq(0) > DIV.aem-Grid:eq(0) > DIV.responsivegrid:eq(0) > DIV.aem-Grid:eq(0) > DIV.we-carousel:eq(0) > DIV.cmp-carousel:eq(0) > DIV.cmp-carousel__content:eq(0) > DIV.cmp-carousel__item:eq(0) > DIV.teaser:eq(0) > DIV.cmp-teaser:eq(0) > DIV.cmp-teaser__content:eq(0) > DIV.cmp-teaser__action-container:eq(0) > A.cmp-teaser__action-link:eq(0), Location 1 - HTML > BODY > DIV.container:eq(0) > DIV.root:eq(0) > DIV.aem-Grid:eq(0) > DIV.responsivegrid:eq(0) > DIV.aem-Grid:eq(0) > DIV.we-carousel:eq(0) > DIV.cmp-carousel:eq(0) > DIV.cmp-carousel__content:eq(0) > DIV.cmp-carousel__item:eq(0) > DIV.teaser:eq(0) > DIV.cmp-teaser:eq(0) > DIV.cmp-teaser__content:eq(0) > DIV.cmp-teaser__action-container:eq(0) > A.cmp-teaser__action-link:eq(0), Location 2 - HTML > BODY > DIV.container:eq(0) > DIV.root:eq(0) > DIV.aem-Grid:eq(0) > DIV.responsivegr... once, without stale or duplicate content. | S37: Validate Target metric(s) MY PRIMARY GOAL; action count_once; location - / -; success event -. | U37: Not Started | AA37: Not Started | AC37: Inventory-derived planning row. Risk: High. Custom code: Yes - offer template evidence. Shared-location activity count indicator: 1.
