Workbook
Name Total_Minutes_Worked: DA!$L:$L

Sheet RU
D4: Sky Martech - Consent Management & Cookie Remediation Resource Utilization
D8: Select Week | F8: Overall RU | J8: Cookie Remediation RU | N8: Consent Management RU | R8: # FTEs | T8: Work Days | V8: Work Hours | X8: Holidays
D10: (10-Aug-26 To 14-Aug-26) | F10: =Calc!I11 -> 0.425 | H10: =Calc!J11 -> -0.59375 | J10: =Calc!K11 -> 0.85 | L10: =Calc!L11 -> -0.175 | N10: =Calc!M11 -> 0 | P10: =Calc!N11 -> -1.0125 | R10: =Calc!G11 -> 2 | T10: =Calc!H11 -> 5 | V10: =R10*8*T10 -> 80 | X10: =5-T10 -> 0
D12: Cookie Remediation | H12: Consent Management
D13: Task Type | F13: RU% | H13: Task Type | N13: RU%
D14: =Calc!Q14 -> Analysis & Documentation | F14: =Calc!R14 -> 0.8 | H14: =Calc!U14 -> API Tests | I14: =Calc!V14 -> 0 | J14: =Calc!W14 -> 0 | K14: =Calc!X14 -> 0 | L14: =Calc!Y14 -> Detailed Test Cases | N14: =Calc!V14 -> 0 | O14: =Calc!AB14 -> 0
D15: =Calc!Q15 -> Meetings - CR | F15: =Calc!R15 -> 0.05 | H15: =Calc!U15 -> Automation Test Scripts | I15: =Calc!V15 -> 0 | J15: =Calc!W15 -> 0 | K15: =Calc!X15 -> 0 | L15: =Calc!Y15 -> Analysis/Documentation | N15: =Calc!V15 -> 0
D16: =Calc!Q16 -> Auditing/ObservePoint Setup | F16: =Calc!R16 -> 0 | H16: =Calc!U16 -> Detailed Test Cases | I16: =Calc!V16 -> 0 | J16: =Calc!W16 -> 0 | K16: =Calc!X16 -> 0 | L16: =Calc!Y16 -> Quality Assurance | N16: =Calc!V16 -> 0
D17: =Calc!Q17 -> Quality Assurance - CR | F17: =Calc!R17 -> 0 | H17: =Calc!U17 -> Analysis/Documentation | I17: =Calc!V17 -> 0 | J17: =Calc!W17 -> 0 | K17: =Calc!X17 -> 0 | L17: =Calc!Y17 -> Meetings | N17: =Calc!V17 -> 0
D18: =Calc!Q18 -> Others | F18: =Calc!R18 -> 0 | H18: =Calc!U18 -> Quality Assurance | I18: =Calc!V18 -> 0 | J18: =Calc!W18 -> 0 | K18: =Calc!X18 -> 0 | L18: =Calc!Y18 -> 0 | N18: =Calc!V18 -> 0
H19: =Calc!U19 -> Meetings | I19: =Calc!V19 -> 0 | J19: =Calc!W19 -> 0 | K19: =Calc!X19 -> 0 | L19: =Calc!Y19 -> 0 | N19: =Calc!V19 -> 0
D22: Summary | F22: • Key Deliverables: Consent Management Support: ObservePoint Audit scan reviews, Journey creation in ObservePoint for Glass, Mobile and Broadband for Accept all, Reject all and Essential Only Selection scenarios Cookie Remediation Support: Worked on CONSENT-1032 and CONSENT-1033 requests Shilpa leave on 12th Aug

Sheet DA
A1: Workstream | B1: TaskRelatedTo | C1: Task Type | D1: Task | E1: Requestor | F1: Status | G1: Date | H1: Emp Name | I1: Time Taken | J1: Start Time | K1: End Time | L1: Total Minutes Worked
A2: Consent Management | B2: Web | C2: Automation Test Scripts | D2: Updates to consent test cases to retrieve the list of approved domains using ObservePoint API | E2: James | F2: Completed | G2: 46020 | H2: Susmitha Donthi | I2: 0.29166667 | J2: 0.5 | K2: 0.875 | L2: 420
A3: Consent Management | B3: Web | C3: Meetings | D3: Martech Consent Standup | E3: James | F3: Completed | G3: 46021 | H3: Susmitha Donthi | I3: 0.010416667 | J3: 0.63541667 | K3: 0.64583333 | L3: 15
A4: Consent Management | B4: Web | C4: Automation Test Scripts | D4: Updates to consent test cases to retrieve the list of approved domains using ObservePoint API | E4: James | F4: Completed | G4: 46021 | H4: Susmitha Donthi | I4: 0.29166667 | J4: 0.5 | K4: 0.875 | L4: 420
A5: Consent Management | B5: Web | C5: Automation Test Scripts | D5: Updates to consent test cases to retrieve the list of approved domains using ObservePoint API | E5: James | F5: Completed | G5: 46022 | H5: Susmitha Donthi | I5: 0.29166667 | J5: 0.5 | K5: 0.875 | L5: 420
A6: Consent Management | B6: Web | C6: Automation Test Scripts | D6: Updates to consent test cases to retrieve the list of approved domains using ObservePoint API | E6: James | F6: In Progress | G6: 46024 | H6: Susmitha Donthi | I6: 0.29166667 | J6: 0.5 | K6: 0.875 | L6: 420
A7: Cookie Remediation | B7: Web | C7: Analysis & Documentation | D7: Configured Trade Desk rules in OP, Collected all request URLs for rest of the vendors and documented | E7: James | F7: Completed | G7: 46020 | H7: Shilpa R | I7: 0.29166667 | J7: 0.5 | K7: 0.83333333 | L7: 420
A8: Cookie Remediation | B8: Web | C8: Meetings - CR | D8: Martech Consent Stand Up | E8: James | F8: Completed | G8: 46021 | H8: Shilpa R | I8: 0.010416667 | J8: 0.63541667 | K8: 0.64583333 | L8: 15
A9: Cookie Remediation | B9: Web | C9: Analysis & Documentation | D9: ADDRESSABL-118 Document the criteria to detect client-side processing for TV Squared - went through vendor documentation , analysed implementation on Sky, validated TV Squared through various consent modes and documented the same | E9: James | F9: In Progress | G9: 46021 | H9: Shilpa R | I9: 0.29166667 | J9: 0.51041667 | K9: 0.80208333 | L9: 420
A10: Cookie Remediation | B10: Web | C10: Analysis & Documentation | D10: Configure observe point to detect TV Squared- created rule for present scenario , validated on test audits | E10: James | F10: Completed | G10: 46022 | H10: Shilpa R | I10: 0.33333333 | J10: 0.5 | K10: 0.875 | L10: 480
A11: Cookie Remediation | B11: Web | C11: Analysis & Documentation | D11: ADDRESSABL-111 Document the criteria to detect client-side processing for Flash Talking | E11: James | F11: In Progress | G11: 46024 | H11: Shilpa R | I11: 0.29166667 | J11: 0.5 | K11: 0.83333333 | L11: 420
A12: Cookie Remediation | B12: Web | C12: Analysis & Documentation | D12: Configure observe point to detect Flash Talking- created rule for present scenario , validated on test audits | E12: James | F12: Completed | G12: 46027 | H12: Shilpa R | I12: 0.29166667 | J12: 0.5 | K12: 0.83333333 | L12: 420
A13: Cookie Remediation | B13: Web | C13: Meetings - CR | D13: Martech 2026 Q1 Planning Day 1 - Placeholder | E13: James | F13: Completed | G13: 46028 | H13: Shilpa R | I13: 0.29166667 | J13: 0.64583333 | K13: 0.9375 | L13: 420
... A290: Cookie Remediation | B290: Web | C290: Analysis & Documentation | D290: CONSENT-1012 Started documentation of analyzing various implementation methods and cookies associated with OpenX generally and on sky & skysports pages | E290: James | F290: In Progress | G290: 46140 | H290: Shilpa R | I290: 0.22916667 | J290: 0.52083333 | K290: 0.75 | L290: 330
A291: Cookie Remediation | B291: Web | C291: Analysis & Documentation | D291: CONSENT-934 AdobeCJA rules failed in OP for few pages due to inconsistent schema pattern . Reported this behavior and assigned to Unni for review | F291: Completed | G291: 46140 | H291: Shilpa R | I291: 0.083333333 | J291: 0.77083333 | K291: 0.875 | L291: 120
A292: Cookie Remediation | B292: Web | C292: Meetings - CR | D292: Tracking tech - Daily Standup | E292: Nick | F292: Completed | G292: 46140 | H292: Shilpa R | I292: 0.020833333 | J292: 0.58333333 | K292: 0.60416667 | L292: 30
A293: Cookie Remediation | B293: Web | C293: Analysis & Documentation | D293: CONSENT-1012 Completed documentation of analyzing various implementation methods and cookies associated with OpenX generally and on sky & skysports pages | E293: James | F293: Completed | G293: 46141 | H293: Shilpa R | I293: 0.19791667 | J293: 0.52083333 | K293: 0.72916667 | L293: 285
A294: Cookie Remediation | B294: Web | C294: Analysis & Documentation | D294: CONSENT-916 Started documentation of analyzing various implementation methods and cookies associated with Spatial Buzz generally and on sky pages | E294: James | F294: In Progress | G294: 46141 | H294: Shilpa R | I294: 0.11458333 | J294: 0.72916667 | K294: 0.89583333 | L294: 165
A295: Cookie Remediation | B295: Web | C295: Meetings - CR | D295: Tracking tech - Daily Standup | E295: Nick | F295: Completed | G295: 46141 | H295: Shilpa R | I295: 0.020833333 | J295: 0.58333333 | K295: 0.60416667 | L295: 30
A296: Cookie Remediation | B296: Web | C296: Analysis & Documentation | D296: CONSENT-916 Completed documentation of analyzing various implementation methods and cookies associated with Spatial Buzz generally and on sky pages | E296: James | F296: In Progress | G296: 46142 | H296: Shilpa R | I296: 0.29166667 | J296: 0.5 | K296: 0.83333333 | L296: 420
A297: Cookie Remediation | B297: Web | C297: Meetings - CR | D297: Tracking tech - Daily Standup | E297: Nick | F297: Completed | G297: 46142 | H297: Shilpa R | I297: 0.020833333 | J297: 0.58333333 | K297: 0.60416667 | L297: 30
A298: Cookie Remediation | B298: Web | C298: Analysis & Documentation | D298: CONSENT-916 Configured observe point to detect Spatial Buzz - created rule for present scenario,absent scenario , validated on test audits | E298: James | F298: Completed | G298: 46146 | H298: Shilpa R | I298: 0.16666667 | J298: 0.5 | K298: 0.625 | L298: 240
A299: Cookie Remediation | B299: Web | C299: Analysis & Documentation | D299: CONSENT-941 Started documentation of analyzing various implementation methods and cookies associated with Content Stack generally and on sky pages | E299: James | F299: In Progress | G299: 46146 | H299: Shilpa R | I299: 0.14583333 | J299: 0.625 | K299: 0.85416667 | L299: 210
A300: Cookie Remediation | B300: Web | C300: Meetings - CR | D300: Tracking tech - Daily Standup | E300: Nick | F300: Completed | G300: 46146 | H300: Shilpa R | I300: 0.020833333 | J300: 0.58333333 | K300: 0.60416667 | L300: 30
A301: Cookie Remediation | B301: Web | C301: Analysis & Documentation | D301: CONSENT-941 Completed documentation of analyzing various implementation methods and cookies associated with Content Stack generally and on sky pages | E301: James | F301: Completed | G301: 46147 | H301: Shilpa R | I301: 0.3125 | J301: 0.52083333 | K301: 0.875 | L301: 450
A302: Cookie Remediation | B302: Web | C302: Meetings - CR | D302: Tracking tech - Daily Standup | E302: Nick | F302: Completed | G302: 46147 | H302: Shilpa R | I302: 0.020833333 | J302: 0.58333333 | K302: 0.60416667 | L302: 30
A303: Cookie Remediation | B303: Web | C303: Analysis & Documentation | D303: CONSENT-941 Configured observe point to detect Content Stack - created rule for present scenario,absent scenario , validated on test audits | E303: James | F303: Completed | G303: 46148 | H303: Shilpa R | I303: 0.16666667 | J303: 0.5 | K303: 0.625 | L303: 240
... A323: Cookie Remediation | B323: Web | C323: Analysis & Documentation | D323: CONSENT-961 Completed documentation of analyzing various implementation methods and cookies associated with cloudfront generally and on sky pages | E323: James | F323: Completed | G323: 46156 | H323: Shilpa R | I323: 0.16666667 | J323: 0.5 | K323: 6.6666667 | L323: 240
A324: Cookie Remediation | B324: Web | C324: Analysis & Documentation | D324: CONSENT-953 Started documentation of analyzing various implementation methods and cookies associated with Yext generally and on sky pages | F324: In Progress | G324: 46156 | H324: Shilpa R | I324: 0.16666667 | J324: 0.66666667 | K324: 6.875 | L324: 240
A325: Cookie Remediation | B325: Web | C325: Meetings - CR | D325: Tracking tech - Daily Standup | E325: Nick | F325: Completed | G325: 46156 | H325: Shilpa R | I325: 0.020833333 | J325: 0.58333333 | K325: 0.60416667 | L325: 30
A326: Cookie Remediation | B326: Web | C326: Analysis & Documentation | D326: CONSENT-953 Completed documentation of analyzing various implementation methods and cookies associated with Yext generally and on sky pages | E326: James | F326: Completed | G326: 46157 | H326: Shilpa R | I326: 0.32291667 | J326: 0.52083333 | K326: 0.8125 | L326: 465
A327: Cookie Remediation | B327: Web | C327: Meetings - CR | D327: Tracking tech - Daily Standup | E327: Nick | F327: Completed | G327: 46157 | H327: Shilpa R | I327: 0.020833333 | J327: 0.58333333 | K327: 0.60416667 | L327: 30
A328: Consent Management | B328: Web | C328: Meetings | D328: Tracking tech - Daily Standup | E328: Nick | F328: Completed | G328: 46153 | H328: Susmitha Donthi | I328: 0.020833333 | J328: 0.58333333 | K328: 0.60416667 | L328: 30
A329: Consent Management | B329: Web | C329: Analysis/Documentation | D329: Updates to Jira tickets/bugs for app logs to include parameter level confirmations | E329: Masoud | F329: Completed | G329: 46153 | H329: Susmitha Donthi | I329: 0.33333333 | J329: 0.5 | K329: 0.875 | L329: 480
A330: Consent Management | B330: Web | C330: Meetings | D330: Tracking tech - Daily Standup | E330: Nick | F330: Completed | G330: 46155 | H330: Susmitha Donthi | I330: 0.020833333 | J330: 0.58333333 | K330: 0.60416667 | L330: 30
A331: Consent Management | B331: Web | C331: ObservePoint Setup | D331: Uploaded revised iOS app logs for UKI Sky News to ObservePoint and added observations to the Jira ticket | E331: Masoud | F331: Completed | G331: 46154 | H331: Susmitha Donthi | I331: 0.25 | J331: 0.5 | K331: 0.89583333 | L331: 360
A332: Consent Management | B332: Web | C332: Meetings | D332: Tracking tech - Daily Standup | E332: Nick | F332: Completed | G332: 46155 | H332: Susmitha Donthi | I332: 0.020833333 | J332: 0.58333333 | K332: 0.60416667 | L332: 30
A333: Consent Management | B333: Web | C333: ObservePoint Setup | D333: Performed ObservePoint audit scans review for the pending weeks and uploaded the document into the Shared Folder | E333: Masoud | F333: Completed | G333: 46155 | H333: Susmitha Donthi | I333: 0.33333333 | J333: 0.5 | K333: 0.89583333 | L333: 480
A334: Consent Management | B334: Web | C334: Meetings | D334: Tracking tech - Daily Standup | E334: Nick | F334: Completed | G334: 46156 | H334: Susmitha Donthi | I334: 0.020833333 | J334: 0.58333333 | K334: 0.60416667 | L334: 30
A335: Consent Management | B335: Web | C335: ObservePoint Setup | D335: Performed ObservePoint audit scans review for the pending weeks and uploaded the document into the Shared Folder | E335: Masoud | F335: In Progress | G335: 46156 | H335: Susmitha Donthi | I335: 0.33333333 | J335: 0.5 | K335: 0.89583333 | L335: 480
...

Sheet Task Tracker
A1: Sr. No. | B1: Workstream | C1: Task Name | D1: Task Type | E1: Requestor | F1: Task Owner | G1: Status | H1: Request Date | I1: Start Date | J1: Target Delivery Date | K1: Actual Delivery Date | L1: Remarks | M1: Week
A2: 1 | B2: Consent Management | C2: Updates to consent test cases to retrieve the list of approved domains | D2: Coding for Automation | E2: James | F2: Susmitha Donthi | G2: In Progress | H2: 46020 | I2: 46020 | L2: Updates to consent test cases to retrieve the list of approved domains utilizing ObservePoint API | M2: 46020
A3: 2 | B3: Cookie Remediation | C3: Configured Trade Desk rules in OP, Collected all request URLs for rest of the vendors and documented | D3: Auditing/ObservePoint Setup | E3: James | F3: Shilpa R | G3: Completed | H3: 46017 | I3: 46017 | J3: 46020 | K3: 46020 | L3: Analyzed root cause and gathered additional request URLs | M3: 46020
A4: 3 | B4: Cookie Remediation | C4: ADDRESSABL-118 Document the criteria to detect client-side processing for TV Squared & Configure observe point to detect TV Squared | D4: Auditing/ObservePoint Setup | E4: James | F4: Shilpa R | G4: Completed | H4: 46021 | I4: 46021 | J4: 46022 | K4: 46022 | L4: Document criteria to detect client side processing for Tik Tok and Configured audit and rules in observe point for Tik Tok | M4: 46020
A5: 4 | B5: Cookie Remediation | C5: ADDRESSABL-111 Document the criteria to detect client-side processing for Flash Talking | D5: Auditing/ObservePoint Setup | E5: James | F5: Shilpa R | G5: In Progress | H5: 46024 | I5: 46024 | L5: Document criteria to detect client side processing for Trade Desk | M5: 46020
A6: 5 | B6: Cookie Remediation | C6: ADDRESSABL-118 Configure observe point to detect Flash Talking | D6: Auditing/ObservePoint Setup | E6: James | F6: Shilpa R | G6: Completed | H6: 46027 | I6: 46027 | J6: 46027 | K6: 46027 | L6: Configured audit and rules in observe point for Flash Talking | M6: 46027
A7: 6 | B7: Cookie Remediation | C7: ADDRESSABL-121 Document the criteria to detect client-side processing for Quant cast & Configure observe point to detect Quant cast | D7: Auditing/ObservePoint Setup | E7: James | F7: Shilpa R | G7: Completed | H7: 46028 | I7: 46028 | J7: 46030 | K7: 46030 | L7: Document criteria to detect client side processing for Quantcast and Configured audit and rules in observe point for Quantcast | M7: 46027
A8: 7 | B8: Cookie Remediation | C8: ADDRESSABL-117 Document the criteria to detect client-side processing for Xcorp | D8: Auditing/ObservePoint Setup | E8: James | F8: Shilpa R | G8: In Progress | H8: 46031 | I8: 46031 | L8: Document criteria to detect client side processing for Xcorp | M8: 46027
A9: 8 | B9: Consent Management | C9: POC to utilize Observepoint Rules API in automation test scripts | D9: Coding for Automation | E9: James | F9: Susmitha Donthi | G9: In Progress | H9: 46027 | I9: 46027 | L9: consent test cases code changes to utilize rules API | M9: 46027
A10: 9 | B10: Cookie Remediation | C10: ADDRESSABL-117 Document the criteria to detect client-side processing for Xcorp & Configure observe point to detect XCorp | D10: Auditing/ObservePoint Setup | E10: James | F10: Shilpa R | G10: Completed | H10: 46031 | I10: 46031 | J10: 46038 | K10: 46038 | L10: Document criteria to detect client side processing for Xcorp and Configured audit and rules in observe point for Xcorp | M10: 46034
A11: 10 | B11: Consent Management | C11: Changes to consent automation test scripts to utilize Rules API | D11: Coding for Automation | E11: James | F11: Susmitha Donthi | G11: In Progress | H11: 46034 | I11: 46034 | L11: Consent test cases code changes to utilize rules API | M11: 46034
A12: 11 | B12: Cookie Remediation | C12: CONSENT-911 Document the criteria to detect client-side processing for Amazon & Configure observe point to detect Amazon | D12: Auditing/ObservePoint Setup | E12: James | F12: Shilpa R | G12: Completed | H12: 46041 | I12: 46041 | J12: 46043 | K12: 46043 | L12: Document criteria to detect client side processing for Amazon and Configured audit and rules in observe point for Amazon | M12: 46041
A13: 12 | B13: Cookie Remediation | C13: CONSENT-1006 Document the criteria to detect client-side processing for Clicktale & Configure observe point to detect Clicktale | D13: Auditing/ObservePoint Setup | E13: James | F13: Shilpa R | G13: Completed | H13: 46044 | I13: 46044 | J13: 46045 | K13: 46045 | L13: Document criteria to detect client side processing for Clicktale and Configured audit and rules in observe point for Clicktale | M13: 46041
A14: 13 | B14: Cookie Remediation | C14: CONSENT-927 Document the criteria to detect client-side processing for Brightcove | D14: Auditing/ObservePoint Setup | E14: James | F14: Shilpa R | G14: In Progress | H14: 46045 | I14: 46045 | L14: Document criteria to detect client side processing for Brightcove | M14: 46041
A15: 14 | B15: Consent Management | C15: OneTrust documentation analysis to understand how OneTrust calculates daily unique visitors and analyzing cross domain and cross device consent feature in OneTrust | D15: Analysis/Documentation | E15: James | F15: Susmitha Donthi | G15: In Progress | H15: 46043 | I15: 46043 | J15: 46045 | K15: 46045 | L15: OneTrust documentation analysis | M15: 46041
A16: 15 | B16: Consent Management | C16: Reviewing ObservePoint Audit scans and documenting new unapproved cookies identified | D16: Analysis/Documentation | E16: Masoud | F16: Susmitha Donthi | G16: Completed | H16: 46042 | I16: 46042 | J16: 46043 | K16: 46043 | L16: Observepoint audit scans review | M16: 46041
A17: 16 | B17: Consent Management | C17: Adobe Analytics data analysis and dashboard creation for sky.com data | D17: Analysis/Documentation | E17: James | F17: Susmitha Donthi | G17: In Progress | H17: 46045 | I17: 46045 | L17: Adobe Analytics dashboard creation and traffic analysis for sky.com | M17: 46041
A18: 17 | B18: Cookie Remediation | C18: CONSENT-927 Document the criteria to detect client-side processing for Brightcove & Configure observe point to detect Brightcove | D18: Auditing/ObservePoint Setup | E18: James | F18: Shilpa R | G18: Completed | H18: 46045 | I18: 46045 | J18: 46049 | K18: 46049 | L18: Document criteria to detect client side processing for Brightcove and Configured audit and rules in observe point for Brightcove | M18: 46048
A19: 18 | B19: Cookie Remediation | C19: CONSENT-963 Document the criteria to detect client-side processing for Xandr & Configure observe point to detect Xandr | D19: Auditing/ObservePoint Setup | E19: James | F19: Shilpa R | G19: Completed | H19: 46050 | I19: 46050 | J19: 46051 | K19: 46051 | L19: Document criteria to detect client side processing for Xandr and Configured audit and rules in observe point for Xandr | M19: 46048
A20: 19 | B20: Cookie Remediation | C20: CONSENT-914 Document the criteria to detect client-side processing for Liveperson | D20: Auditing/ObservePoint Setup | E20: James | F20: Shilpa R | G20: In Progress | H20: 46052 | I20: 46052 | L20: Document criteria to detect client side processing for Liveperson | M20: 46048
A21: 20 | B21: Consent Management | C21: Adobe Analytics Dashboard to calculate the average unique visitors for Sky.com, Sky Sports and Sky News - Websites and Apps | D21: Analysis/Documentation | E21: James | F21: Susmitha Donthi | G21: Completed | H21: 46045 | I21: 46045 | J21: 46052 | K21: 46052 | L21: Adobe Analytics Dashboard to calculate the average unique visitors for Sky.com, Sky Sports and Sky News - Websites and Apps | M21: 46048
A22: 21 | B22: Consent Management | C22: Reviewing ObservePoint Audit scans and documenting new unapproved cookies identified | D22: Analysis/Documentation | E22: Masoud | F22: Susmitha Donthi | G22: Completed | H22: 46049 | I22: 46049 | J22: 46050 | K22: 46050 | L22: Observepoint audit scans review | M22: 46048
A23: 22 | B23: Consent Management | C23: Calculate Estimated daily unique visitors to Sky.com, Sky Sports and Sky News Websites and apps | D23: Analysis/Documentation | E23: James | F23: Susmitha Donthi | G23: Completed | H23: 46045 | I23: 46045 | J23: 46052 | K23: 46052 | L23: Calculated Estimated daily unique visitors to Sky.com, Sky Sports and Sky News Websites and apps based on the average unique visitors in Adobe analytics and acceptance rate in SourcePoint | M23: 46048
A24: 23 | B24: Cookie Remediation | C24: CONSENT-914 Configure observe point to detect Liveperson | D24: Auditing/ObservePoint Setup | E24: James | F24: Shilpa R | G24: Completed | H24: 46052 | I24: 46052 | J24: 46055 | K24: 46055 | L24: Configured audit and rules in observe point for Liveperson | M24: 46055
A25: 24 | B25: Cookie Remediation | C25: CONSENT-923 Document the criteria to detect client-side processing for Adobe Launch & Configure observe point to detect Adobe Launch | D25: Auditing/ObservePoint Setup | E25: James | F25: Shilpa R | G25: Completed | H25: 46056 | I25: 46056 | J25: 46057 | K25: 46057 | L25: Document criteria to detect client side processing for Xandr and Configured audit and rules in observe point for Xandr | M25: 46055
A26: 25 | B26: Cookie Remediation | C26: CONSENT-943 Document the criteria to detect client-side processing for Dynatrace | D26: Auditing/ObservePoint Setup | E26: James | F26: Shilpa R | G26: Completed | H26: 46059 | I26: 46059 | L26: Document criteria to detect client side processing for Liveperson | M26: 46055
A27: 26 | B27: Consent Management | C27: Updated pre-audit actions of the Observepoint audits where incorrect website details are added | D27: Analysis/Documentation | E27: Masoud | F27: Susmitha Donthi | G27: Completed | H27: 46057 | I27: 46057 | J27: 46058 | K27: 46058 | L27: Updated pre-audit actions of the Observepoint audits where incorrect details are added | M27: 46055
A28: 27 | B28: Consent Management | C28: Reviewing ObservePoint Audit scans, document new unapproved cookies identified, identify the vendor of the cookies identified, verify if the vendor is listed on CMP | D28: Analysis/Documentation | E28: Masoud | F28: Susmitha Donthi | G28: In Progress | H28: 46056 | I28: 46056 | L28: Reviewing ObservePoint Audit scans, document new unapproved cookies identified, identify the vendor of the cookies identified, verify if the vendor is listed on CMP | M28: 46055
A29: 28 | B29: Cookie Remediation | C29: CONSENT-943 Configure observe point to detect Dynatrace | D29: Auditing/ObservePoint Setup | E29: James | F29: Shilpa R | G29: Completed | H29: 46059 | I29: 46059 | J29: 46062 | K29: 46062 | L29: Configured audit and rules in observe point for Dynatrace | M29: 46062
A30: 29 | B30: Cookie Remediation | C30: CONSENT-1007 Document the criteria to detect client-side processing for Qualtrics & Configure observe point to detect Qualtrics | D30: Auditing/ObservePoint Setup | E30: James | F30: Shilpa R | G30: Completed | H30: 46063 | I30: 46063 | J30: 46064 | K30: 46064 | L30: Document criteria to detect client side processing for Qualtrics and Configured audit and rules in observe point for Qualtrics | M30: 46062
A31: 30 | B31: Cookie Remediation | C31: CONSENT-922 Document the criteria to detect client-side processing for Bing & Configure observe point to detect Bing | D31: Auditing/ObservePoint Setup | E31: James | F31: Shilpa R | G31: Completed | H31: 46065 | I31: 46065 | J31: 46066 | K31: 46066 | L31: Document criteria to detect client side processing for Bing and Configured audit and rules in observe point for Bing | M31: 46062
A32: 31 | B32: Cookie Remediation | C32: CONSENT-907 Document the criteria to detect client-side processing for Awin | D32: Auditing/ObservePoint Setup | E32: James | F32: Shilpa R | G32: In Progress | H32: 46066 | I32: 46066 | L32: Document criteria to detect client side processing for Awin | M32: 46062
A33: 32 | B33: Consent Management | C33: Updates to SourcePoint acceptance rates considering No choices made and Previous Accept All details and recalculated the associated estimated users on the websites/apps based on the revised acceptance rate | D33: Analysis/Documentation | E33: Masoud | F33: Susmitha Donthi | G33: Completed | H33: 46062 | I33: 46062 | J33: 46063 | K33: 46063 | L33: Updates to SourcePoint acceptance rates considering No choices made and Previous Accept All details and recalculated the associated estimated users on the websites/apps based on the revised acceptance rate | M33: 46062
A34: 33 | B34: Consent Management | C34: Reviewing ObservePoint Audit scans, document new unapproved cookies identified, identify the vendor of the cookies identified, verify if the vendor is listed on CMP | D34: Analysis/Documentation | E34: Masoud | F34: Susmitha Donthi | G34: Completed | H34: 46063 | I34: 46063 | J34: 46065 | K34: 46065 | L34: Reviewing ObservePoint Audit scans, document new unapproved cookies identified, identify the vendor of the cookies identified, verify if the vendor is listed on CMP | M34: 46062
A35: 34 | B35: Cookie Remediation | C35: CONSENT-907 Document the criteria to detect client-side processing for Awin & Configure observe point to detect Awin | D35: Auditing/ObservePoint Setup | E35: James | F35: Shilpa R | G35: Completed | H35: 46066 | I35: 46066 | J35: 46070 | K35: 46070 | L35: Document criteria to detect client side processing for Awin and Configured audit and rules in observe point for Awin | M35: 46069
A36: 35 | B36: Cookie Remediation | C36: CONSENT-933 Document the criteria to detect client-side processing for Pinterest | D36: Auditing/ObservePoint Setup | E36: James | F36: Shilpa R | G36: Completed | H36: 46071 | I36: 46071 | J36: 46071 | K36: 46071 | L36: Document criteria to detect client side processing for pinterest | M36: 46069
A37: 36 | B37: Cookie Remediation | C37: CONSENT-919 Document the criteria to detect client-side processing for Adobe Target | D37: Auditing/ObservePoint Setup | E37: James | F37: Shilpa R | G37: Completed | H37: 46072 | I37: 46072 | J37: 46072 | K37: 46072 | L37: Document criteria to detect client side processing for Adobe Target | M37: 46069
A38: 37 | B38: Cookie Remediation | C38: CONSENT-997 Document the criteria to detect client-side processing for Source point | D38: Auditing/ObservePoint Setup | E38: James | F38: Shilpa R | G38: In Progress | H38: 46073 | I38: 46073 | L38: Document criteria to detect client side processing for Source point | M38: 46069
A39: 38 | B39: Consent Management | C39: ADDRESSABL- 331 - Review of cookies and regex pattern updates to Sky Italy Consent Categories | D39: Analysis/Documentation | E39: James | F39: Susmitha Donthi | G39: Completed | H39: 46069 | I39: 46069 | J39: 46073 | K39: 46073 | L39: Review of cookies and regex pattern updates to Sky Italy Consent Categories | M39: 46069
A40: 39 | B40: Consent Management | C40: ADDRESSABL- 336 - Review of cookies and regex pattern updates to Sky Italy Consent Categories | D40: Analysis/Documentation | E40: James | F40: Susmitha Donthi | G40: Completed | H40: 46069 | I40: 46069 | J40: 46073 | K40: 46073 | L40: Review of cookies and regex pattern updates to Sky Italy Consent Categories | M40: 46069
...

Sheet Calc
A1: Eclerx Holiday | B1: =NETWORKDAYS(E11,F11,$A$2:$A$20) -> 5 | I1: Overall | K1: Cookie Remediation | M1: Consent Management | P1: Cookie Remediation | T1: Consent Management
A2: 46023 | B2: New Year's Day | D2: Week | E2: Week Start Date | F2: Week End Date | G2: FTE | H2: WorkDays | I2: RU% | J2: % Change | K2: RU% | L2: % Change | M2: RU% | N2: % Change | P2: Rank | Q2: Task Type | R2: RU% | T2: Rank | U2: Task Type | V2: RU% | Y2: Cookie Remediation Task List
A3: 46037 | B3: Maharashtra elections | D3: ="("&TEXT(E3,"dd-mmm-yy") & " To " &TEXT(E3+4,"dd-mmm-yy")&")" -> (27-Jul-26 To 31-Jul-26) | E3: 46230 | F3: =E3+5 -> 46235 | G3: 2 | H3: =NETWORKDAYS(E3,F3,$A$2:$A$20) -> 5 | I3: =(SUMIFS(Total_Minutes_Worked,DA!$G:$G,">="&Calc!E3,DA!$G:$G,"<="&Calc!F3)/60)/(G3*8*H3) -> 0.825 | J3: - | K3: =(SUMIFS(Total_Minutes_Worked,DA!$G:$G,">="&Calc!E3,DA!$G:$G,"<="&Calc!F3,DA!$A:$A,$K$1)/60)/((G3/2)*8*H3) -> 1.05 | L3: - | M3: =(SUMIFS(Total_Minutes_Worked,DA!$G:$G,">="&Calc!E3,DA!$G:$G,"<="&Calc!F3,DA!$A:$A,$M$1)/60)/((G3/2)*8*H3) -> 0.6 | N3: - | P3: =IF(R3="","",RANK(R3,$R$3:$R$11)+COUNTIF(R$3:R3,R3)-1) -> 3 | Q3: Auditing/ObservePoint Setup | R3: =(SUMIFS(Total_Minutes_Worked,DA!$G:$G,">="&Calc!$E$11,DA!$G:$G,"<="&Calc!$F$11,DA!$C:$C,Calc!$Q3)/60)/(($G$11/2)*8*$H$11) -> 0 | T3: =IF(V3="","",RANK(V3,$V$3:$V$11)+COUNTIF(V$3:V3,V3)-1) -> 1 | U3: API Tests | V3: =(SUMIFS(Total_Minutes_Worked,DA!$G:$G,">="&Calc!$E$11,DA!$G:$G,"<="&Calc!$F$11,DA!$C:$C,Calc!$U3)/60)/(($G$11/2)*8*$H$11) -> 0 | Y3: Analysis & Documentation
A4: 46048 | B4: Republic Day | D4: ="("&TEXT(E4,"dd-mmm-yy") & " To " &TEXT(E4+4,"dd-mmm-yy")&")" -> (03-Aug-26 To 07-Aug-26) | E4: =E3+7 -> 46237 | F4: =E4+5 -> 46242 | G4: 2 | H4: =NETWORKDAYS(E4,F4,$A$2:$A$20) -> 5 | I4: =(SUMIFS(Total_Minutes_Worked,DA!$G:$G,">="&Calc!E4,DA!$G:$G,"<="&Calc!F4)/60)/(G4*8*H4) -> 1.01875 | J4: =I4-I3 -> 0.19375 | K4: =(SUMIFS(Total_Minutes_Worked,DA!$G:$G,">="&Calc!E4,DA!$G:$G,"<="&Calc!F4,DA!$A:$A,$K$1)/60)/((G4/2)*8*H4) -> 1.025 | L4: =K4-K3 -> -0.025 | M4: =(SUMIFS(Total_Minutes_Worked,DA!$G:$G,">="&Calc!E4,DA!$G:$G,"<="&Calc!F4,DA!$A:$A,$M$1)/60)/((G4/2)*8*H4) -> 1.0125 | N4: =M4-M3 -> 0.4125 | P4: =IF(R4="","",RANK(R4,$R$3:$R$11)+COUNTIF(R$3:R4,R4)-1) -> 2 | Q4: Meetings - CR | R4: =(SUMIFS(Total_Minutes_Worked,DA!$G:$G,">="&Calc!$E$11,DA!$G:$G,"<="&Calc!$F$11,DA!$C:$C,Calc!$Q4)/60)/(($G$11/2)*8*$H$11) -> 0.05 | T4: =IF(V4="","",RANK(V4,$V$3:$V$11)+COUNTIF(V$3:V4,V4)-1) -> 2 | U4: Automation Test Scripts | V4: =(SUMIFS(Total_Minutes_Worked,DA!$G:$G,">="&Calc!$E$11,DA!$G:$G,"<="&Calc!$F$11,DA!$C:$C,Calc!$U4)/60)/(($G$11/2)*8*$H$11) -> 0 | Y4: Meetings - CR
A5: 46084 | B5: Holi | D5: ="("&TEXT(E5,"dd-mmm-yy") & " To " &TEXT(E5+4,"dd-mmm-yy")&")" -> (10-Aug-26 To 14-Aug-26) | E5: =E4+7 -> 46244 | F5: =E5+5 -> 46249 | G5: 2 | H5: =NETWORKDAYS(E5,F5,$A$2:$A$20) -> 5 | I5: =(SUMIFS(Total_Minutes_Worked,DA!$G:$G,">="&Calc!E5,DA!$G:$G,"<="&Calc!F5)/60)/(G5*8*H5) -> 0.425 | J5: =I5-I4 -> -0.59375 | K5: =(SUMIFS(Total_Minutes_Worked,DA!$G:$G,">="&Calc!E5,DA!$G:$G,"<="&Calc!F5,DA!$A:$A,$K$1)/60)/((G5/2)*8*H5) -> 0.85 | L5: =K5-K4 -> -0.175 | M5: =(SUMIFS(Total_Minutes_Worked,DA!$G:$G,">="&Calc!E5,DA!$G:$G,"<="&Calc!F5,DA!$A:$A,$M$1)/60)/((G5/2)*8*H5) -> 0 | N5: =M5-M4 -> -1.0125 | P5: =IF(R5="","",RANK(R5,$R$3:$R$11)+COUNTIF(R$3:R5,R5)-1) -> 4 | Q5: Quality Assurance - CR | R5: =(SUMIFS(Total_Minutes_Worked,DA!$G:$G,">="&Calc!$E$11,DA!$G:$G,"<="&Calc!$F$11,DA!$C:$C,Calc!$Q5)/60)/(($G$11/2)*8*$H$11) -> 0 | T5: =IF(V5="","",RANK(V5,$V$3:$V$11)+COUNTIF(V$3:V5,V5)-1) -> 3 | U5: Detailed Test Cases | V5: =(SUMIFS(Total_Minutes_Worked,DA!$G:$G,">="&Calc!$E$11,DA!$G:$G,"<="&Calc!$F$11,DA!$C:$C,Calc!$U5)/60)/(($G$11/2)*8*$H$11) -> 0 | Y5: Auditing/ObservePoint Setup
A6: 46101 | B6: Eid-ul Fitr | D6: ="("&TEXT(E6,"dd-mmm-yy") & " To " &TEXT(E6+4,"dd-mmm-yy")&")" -> (17-Aug-26 To 21-Aug-26) | E6: =E5+7 -> 46251 | F6: =E6+5 -> 46256 | G6: 2 | H6: =NETWORKDAYS(E6,F6,$A$2:$A$20) -> 5 | I6: =(SUMIFS(Total_Minutes_Worked,DA!$G:$G,">="&Calc!E6,DA!$G:$G,"<="&Calc!F6)/60)/(G6*8*H6) -> 0 | J6: =I6-I5 -> -0.425 | K6: =(SUMIFS(Total_Minutes_Worked,DA!$G:$G,">="&Calc!E6,DA!$G:$G,"<="&Calc!F6,DA!$A:$A,$K$1)/60)/((G6/2)*8*H6) -> 0 | L6: =K6-K5 -> -0.85 | M6: =(SUMIFS(Total_Minutes_Worked,DA!$G:$G,">="&Calc!E6,DA!$G:$G,"<="&Calc!F6,DA!$A:$A,$M$1)/60)/((G6/2)*8*H6) -> 0 | N6: =M6-M5 -> 0 | P6: =IF(R6="","",RANK(R6,$R$3:$R$11)+COUNTIF(R$3:R6,R6)-1) -> 1 | Q6: Analysis & Documentation | R6: =(SUMIFS(Total_Minutes_Worked,DA!$G:$G,">="&Calc!$E$11,DA!$G:$G,"<="&Calc!$F$11,DA!$C:$C,Calc!$Q6)/60)/(($G$11/2)*8*$H$11) -> 0.8 | T6: =IF(V6="","",RANK(V6,$V$3:$V$11)+COUNTIF(V$3:V6,V6)-1) -> 4 | U6: Analysis/Documentation | V6: =(SUMIFS(Total_Minutes_Worked,DA!$G:$G,">="&Calc!$E$11,DA!$G:$G,"<="&Calc!$F$11,DA!$C:$C,Calc!$U6)/60)/(($G$11/2)*8*$H$11) -> 0 | Y6: Quality Assurance
A7: 46115 | B7: Good Friday | D7: ="("&TEXT(E7,"dd-mmm-yy") & " To " &TEXT(E7+4,"dd-mmm-yy")&")" -> (24-Aug-26 To 28-Aug-26) | E7: =E6+7 -> 46258 | F7: =E7+5 -> 46263 | G7: 2 | H7: =NETWORKDAYS(E7,F7,$A$2:$A$20) -> 5 | I7: =(SUMIFS(Total_Minutes_Worked,DA!$G:$G,">="&Calc!E7,DA!$G:$G,"<="&Calc!F7)/60)/(G7*8*H7) -> 0 | J7: =I7-I6 -> 0 | K7: =(SUMIFS(Total_Minutes_Worked,DA!$G:$G,">="&Calc!E7,DA!$G:$G,"<="&Calc!F7,DA!$A:$A,$K$1)/60)/((G7/2)*8*H7) -> 0 | L7: =K7-K6 -> 0 | M7: =(SUMIFS(Total_Minutes_Worked,DA!$G:$G,">="&Calc!E7,DA!$G:$G,"<="&Calc!F7,DA!$A:$A,$M$1)/60)/((G7/2)*8*H7) -> 0 | N7: =M7-M6 -> 0 | P7: =IF(R7="","",RANK(R7,$R$3:$R$11)+COUNTIF(R$3:R7,R7)-1) -> 5 | Q7: Others | R7: =(SUMIFS(Total_Minutes_Worked,DA!$G:$G,">="&Calc!$E$11,DA!$G:$G,"<="&Calc!$F$11,DA!$C:$C,Calc!$Q7)/60)/(($G$11/2)*8*$H$11) -> 0 | T7: =IF(V7="","",RANK(V7,$V$3:$V$11)+COUNTIF(V$3:V7,V7)-1) -> 5 | U7: Quality Assurance | V7: =(SUMIFS(Total_Minutes_Worked,DA!$G:$G,">="&Calc!$E$11,DA!$G:$G,"<="&Calc!$F$11,DA!$C:$C,Calc!$U7)/60)/(($G$11/2)*8*$H$11) -> 0 | Y7: Others
A8: 46143 | B8: International Worker's Day | D8: ="("&TEXT(E8,"dd-mmm-yy") & " To " &TEXT(E8+4,"dd-mmm-yy")&")" -> (31-Aug-26 To 04-Sep-26) | E8: =E7+7 -> 46265 | F8: =E8+5 -> 46270 | G8: 2 | H8: =NETWORKDAYS(E8,F8,$A$2:$A$20) -> 5 | I8: =(SUMIFS(Total_Minutes_Worked,DA!$G:$G,">="&Calc!E8,DA!$G:$G,"<="&Calc!F8)/60)/(G8*8*H8) -> 0 | J8: =I8-I7 -> 0 | K8: =(SUMIFS(Total_Minutes_Worked,DA!$G:$G,">="&Calc!E8,DA!$G:$G,"<="&Calc!F8,DA!$A:$A,$K$1)/60)/((G8/2)*8*H8) -> 0 | L8: =K8-K7 -> 0 | M8: =(SUMIFS(Total_Minutes_Worked,DA!$G:$G,">="&Calc!E8,DA!$G:$G,"<="&Calc!F8,DA!$A:$A,$M$1)/60)/((G8/2)*8*H8) -> 0 | N8: =M8-M7 -> 0 | P8: =IF(R8="","",RANK(R8,$R$3:$R$11)+COUNTIF(R$3:R8,R8)-1) -> 6 | R8: =(SUMIFS(Total_Minutes_Worked,DA!$G:$G,">="&Calc!$E$11,DA!$G:$G,"<="&Calc!$F$11,DA!$C:$C,Calc!$Q8)/60)/(($G$11/2)*8*$H$11) -> 0 | T8: =IF(V8="","",RANK(V8,$V$3:$V$11)+COUNTIF(V$3:V8,V8)-1) -> 6 | U8: Meetings | V8: =(SUMIFS(Total_Minutes_Worked,DA!$G:$G,">="&Calc!$E$11,DA!$G:$G,"<="&Calc!$F$11,DA!$C:$C,Calc!$U8)/60)/(($G$11/2)*8*$H$11) -> 0
A9: 46279 | B9: Ganesh Chaturthi | D9: ="("&TEXT(E9,"dd-mmm-yy") & " To " &TEXT(E9+4,"dd-mmm-yy")&")" -> (07-Sep-26 To 11-Sep-26) | E9: =E8+7 -> 46272 | F9: =E9+5 -> 46277 | G9: 2 | H9: =NETWORKDAYS(E9,F9,$A$2:$A$20) -> 5 | I9: =(SUMIFS(Total_Minutes_Worked,DA!$G:$G,">="&Calc!E9,DA!$G:$G,"<="&Calc!F9)/60)/(G9*8*H9) -> 0 | J9: =I9-I8 -> 0 | K9: =(SUMIFS(Total_Minutes_Worked,DA!$G:$G,">="&Calc!E9,DA!$G:$G,"<="&Calc!F9,DA!$A:$A,$K$1)/60)/((G9/2)*8*H9) -> 0 | L9: =K9-K8 -> 0 | M9: =(SUMIFS(Total_Minutes_Worked,DA!$G:$G,">="&Calc!E9,DA!$G:$G,"<="&Calc!F9,DA!$A:$A,$M$1)/60)/((G9/2)*8*H9) -> 0 | N9: =M9-M8 -> 0 | P9: =IF(R9="","",RANK(R9,$R$3:$R$11)+COUNTIF(R$3:R9,R9)-1) -> 7 | R9: =(SUMIFS(Total_Minutes_Worked,DA!$G:$G,">="&Calc!$E$11,DA!$G:$G,"<="&Calc!$F$11,DA!$C:$C,Calc!$Q9)/60)/(($G$11/2)*8*$H$11) -> 0 | T9: =IF(V9="","",RANK(V9,$V$3:$V$11)+COUNTIF(V$3:V9,V9)-1) -> 7 | U9: Coding for Automation | V9: =(SUMIFS(Total_Minutes_Worked,DA!$G:$G,">="&Calc!$E$11,DA!$G:$G,"<="&Calc!$F$11,DA!$C:$C,Calc!$U9)/60)/(($G$11/2)*8*$H$11) -> 0
A10: 46297 | B10: Mahatma Gandhi Jayanti | P10: =IF(R10="","",RANK(R10,$R$3:$R$11)+COUNTIF(R$3:R10,R10)-1) -> 8 | R10: =(SUMIFS(Total_Minutes_Worked,DA!$G:$G,">="&Calc!$E$11,DA!$G:$G,"<="&Calc!$F$11,DA!$C:$C,Calc!$Q10)/60)/(($G$11/2)*8*$H$11) -> 0 | T10: =IF(V10="","",RANK(V10,$V$3:$V$11)+COUNTIF(V$3:V10,V10)-1) -> 8 | U10: Grafana Dashboard | V10: =(SUMIFS(Total_Minutes_Worked,DA!$G:$G,">="&Calc!$E$11,DA!$G:$G,"<="&Calc!$F$11,DA!$C:$C,Calc!$U10)/60)/(($G$11/2)*8*$H$11) -> 0
A11: 46315 | B11: Dussehra | D11: Selected week | E11: =VLOOKUP(RU!$D$10,Calc!$D$4:$N$9,2,0) -> 46244 | F11: =VLOOKUP(RU!$D$10,Calc!$D$4:$N$9,3,0) -> 46249 | G11: =VLOOKUP(RU!$D$10,Calc!$D$4:$N$9,4,0) -> 2 | H11: =VLOOKUP(RU!$D$10,Calc!$D$4:$N$9,5,0) -> 5 | I11: =VLOOKUP(RU!$D$10,Calc!$D$4:$N$9,6,0) -> 0.425 | J11: =VLOOKUP(RU!$D$10,Calc!$D$4:$N$9,7,0) -> -0.59375 | K11: =VLOOKUP(RU!$D$10,Calc!$D$4:$N$9,8,0) -> 0.85 | L11: =VLOOKUP(RU!$D$10,Calc!$D$4:$N$9,9,0) -> -0.175 | M11: =VLOOKUP(RU!$D$10,Calc!$D$4:$N$9,10,0) -> 0 | N11: =VLOOKUP(RU!$D$10,Calc!$D$4:$N$9,11,0) -> -1.0125 | P11: =IF(R11="","",RANK(R11,$R$3:$R$11)+COUNTIF(R$3:R11,R11)-1) -> 9 | R11: =(SUMIFS(Total_Minutes_Worked,DA!$G:$G,">="&Calc!$E$11,DA!$G:$G,"<="&Calc!$F$11,DA!$C:$C,Calc!$Q11)/60)/(($G$11/2)*8*$H$11) -> 0 | T11: =IF(V11="","",RANK(V11,$V$3:$V$11)+COUNTIF(V$3:V11,V11)-1) -> 9 | U11: ObservePoint Setup | V11: =(SUMIFS(Total_Minutes_Worked,DA!$G:$G,">="&Calc!$E$11,DA!$G:$G,"<="&Calc!$F$11,DA!$C:$C,Calc!$U11)/60)/(($G$11/2)*8*$H$11) -> 0 | Y11: Consent Management Task List
A12: 46335 | B12: Diwali holiday | Y12: API Tests
A13: 46381 | B13: Christmas | Y13: Automation Test Scripts
D14: Chart | P14: 1 | Q14: =IFERROR(VLOOKUP(P14,$P$3:$R$11,2,0),"") -> Analysis & Documentation | R14: =IFERROR(VLOOKUP(P14,$P$3:$R$11,3,0),"") -> 0.8 | T14: 1 | U14: =IFERROR(VLOOKUP(T14,$T$3:$V$11,2,0),"") -> API Tests | V14: =IFERROR(VLOOKUP(T14,$T$3:$V$11,3,0),"") -> 0 | Y14: Detailed Test Cases
D15: Week | E15: Cookie Remediation RU% | F15: Consent Management RU% | P15: 2 | Q15: =IFERROR(VLOOKUP(P15,$P$3:$R$11,2,0),"") -> Meetings - CR | R15: =IFERROR(VLOOKUP(P15,$P$3:$R$11,3,0),"") -> 0.05 | T15: 2 | U15: =IFERROR(VLOOKUP(T15,$T$3:$V$11,2,0),"") -> Automation Test Scripts | V15: =IFERROR(VLOOKUP(T15,$T$3:$V$11,3,0),"") -> 0 | Y15: Analysis/Documentation
D16: =TEXT($E4,"dd MMM") -> 03 Aug | E16: =$K4 -> 1.025 | F16: =$M4 -> 1.0125 | P16: 3 | Q16: =IFERROR(VLOOKUP(P16,$P$3:$R$11,2,0),"") -> Auditing/ObservePoint Setup | R16: =IFERROR(VLOOKUP(P16,$P$3:$R$11,3,0),"") -> 0 | T16: 3 | U16: =IFERROR(VLOOKUP(T16,$T$3:$V$11,2,0),"") -> Detailed Test Cases | V16: =IFERROR(VLOOKUP(T16,$T$3:$V$11,3,0),"") -> 0 | Y16: Quality Assurance
D17: =TEXT($E5,"dd MMM") -> 10 Aug | E17: =$K5 -> 0.85 | F17: =$M5 -> 0 | P17: 4 | Q17: =IFERROR(VLOOKUP(P17,$P$3:$R$11,2,0),"") -> Quality Assurance - CR | R17: =IFERROR(VLOOKUP(P17,$P$3:$R$11,3,0),"") -> 0 | T17: 4 | U17: =IFERROR(VLOOKUP(T17,$T$3:$V$11,2,0),"") -> Analysis/Documentation | V17: =IFERROR(VLOOKUP(T17,$T$3:$V$11,3,0),"") -> 0 | Y17: Meetings
D18: =TEXT($E6,"dd MMM") -> 17 Aug | E18: =$K6 -> 0 | F18: =$M6 -> 0 | P18: 5 | Q18: =IFERROR(VLOOKUP(P18,$P$3:$R$11,2,0),"") -> Others | R18: =IFERROR(VLOOKUP(P18,$P$3:$R$11,3,0),"") -> 0 | T18: 5 | U18: =IFERROR(VLOOKUP(T18,$T$3:$V$11,2,0),"") -> Quality Assurance | V18: =IFERROR(VLOOKUP(T18,$T$3:$V$11,3,0),"") -> 0
D19: =TEXT($E7,"dd MMM") -> 24 Aug | E19: =$K7 -> 0 | F19: =$M7 -> 0 | P19: 6 | Q19: 0 | R19: =IFERROR(VLOOKUP(P19,$P$3:$R$11,3,0),"") -> 0 | T19: 6 | U19: =IFERROR(VLOOKUP(T19,$T$3:$V$11,2,0),"") -> Meetings | V19: =IFERROR(VLOOKUP(T19,$T$3:$V$11,3,0),"") -> 0
D20: =TEXT($E8,"dd MMM") -> 31 Aug | E20: =$K8 -> 0 | F20: =$M8 -> 0 | P20: 7 | Q20: 0 | R20: =IFERROR(VLOOKUP(P20,$P$3:$R$11,3,0),"") -> 0 | T20: 7 | U20: =IFERROR(VLOOKUP(T20,$T$3:$V$11,2,0),"") -> Coding for Automation | V20: =IFERROR(VLOOKUP(T20,$T$3:$V$11,3,0),"") -> 0
D21: =TEXT($E9,"dd MMM") -> 07 Sep | E21: =$K9 -> 0 | F21: =$M9 -> 0 | P21: 8 | Q21: 0 | R21: =IFERROR(VLOOKUP(P21,$P$3:$R$11,3,0),"") -> 0 | T21: 8 | U21: =IFERROR(VLOOKUP(T21,$T$3:$V$11,2,0),"") -> Grafana Dashboard | V21: =IFERROR(VLOOKUP(T21,$T$3:$V$11,3,0),"") -> 0
P22: 9 | Q22: 0 | R22: =IFERROR(VLOOKUP(P22,$P$3:$R$11,3,0),"") -> 0 | T22: 9 | U22: =IFERROR(VLOOKUP(T22,$T$3:$V$11,2,0),"") -> ObservePoint Setup | V22: =IFERROR(VLOOKUP(T22,$T$3:$V$11,3,0),"") -> 0
